Workbook

Sheet Auditados da semana
A1: Time Tiago — Sales Lab · quem foi auditado e monitorado (semana 05–09/10/2026)
A2: Datas da semana vêm de Resumo!B3:B4. Prioridade: Alta = conf. do mês <70% ou nota de monitoria <65; Média = conf. <85%, nota <75 ou sem monitoria; Baixa = resto.
A4: Closer | B4: Aud. na semana | C4: Conf. na semana | D4: Formulários auditados na semana | E4: Auditado por (semana) | F4: Aud. no mês | G4: Conf. no mês | H4: Monitorias no mês | I4: Nota média monitoria | J4: Última monitoria | K4: Feedbacks pendentes | L4: Prioridade
A5: Andreza Aparecida Sousa Costa | B5: =COUNTIFS(Base!$B$2:$B$1000,$A5,Base!$K$2:$K$1000,">="&Resumo!$B$3,Base!$K$2:$K$1000,"<="&Resumo!$B$4) -> 4 | C5: =IFERROR(AVERAGEIFS(Base!$E$2:$E$1000,Base!$B$2:$B$1000,$A5,Base!$K$2:$K$1000,">="&Resumo!$B$3,Base!$K$2:$K$1000,"<="&Resumo!$B$4),"–") -> 0.5 | D5: Perdidos 4 | E5: Pedro 4 | F5: =COUNTIFS(Base!$B$2:$B$1000,$A5) -> 4 | G5: =AVERAGEIFS(Base!$E$2:$E$1000,Base!$B$2:$B$1000,$A5) -> 0.5 | H5: =COUNTIFS('Base monitorias'!$B$2:$B$41,$A5) -> 1 | I5: =IFERROR(AVERAGEIFS('Base monitorias'!$E$2:$E$41,'Base monitorias'!$B$2:$B$41,$A5),"sem monitoria") -> 55.5 | J5: 55.5 · 05/10 · Pedro · feedback pendente (não enviado) | K5: =COUNTIFS('Base monitorias'!$B$2:$B$41,$A5,'Base monitorias'!$I$2:$I$41,"pendente") -> 1 | L5: Alta
A6: Adriano Robson Gomes | B6: =COUNTIFS(Base!$B$2:$B$1000,$A6,Base!$K$2:$K$1000,">="&Resumo!$B$3,Base!$K$2:$K$1000,"<="&Resumo!$B$4) -> 8 | C6: =IFERROR(AVERAGEIFS(Base!$E$2:$E$1000,Base!$B$2:$B$1000,$A6,Base!$K$2:$K$1000,">="&Resumo!$B$3,Base!$K$2:$K$1000,"<="&Resumo!$B$4),"–") -> 0.525 | D6: Perdidos 5, Rotina 3 | E6: Pedro 8 | F6: =COUNTIFS(Base!$B$2:$B$1000,$A6) -> 14 | G6: =AVERAGEIFS(Base!$E$2:$E$1000,Base!$B$2:$B$1000,$A6) -> 0.57142857 | H6: =COUNTIFS('Base monitorias'!$B$2:$B$41,$A6) -> 1 | I6: =IFERROR(AVERAGEIFS('Base monitorias'!$E$2:$E$41,'Base monitorias'!$B$2:$B$41,$A6),"sem monitoria") -> 52 | J6: 52.0 · 02/10 · Alexandre · feedback aplicado | K6: =COUNTIFS('Base monitorias'!$B$2:$B$41,$A6,'Base monitorias'!$I$2:$I$41,"pendente") -> 0 | L6: Alta
A7: Otavio Augusto Soares Greghi | B7: =COUNTIFS(Base!$B$2:$B$1000,$A7,Base!$K$2:$K$1000,">="&Resumo!$B$3,Base!$K$2:$K$1000,"<="&Resumo!$B$4) -> 1 | C7: =IFERROR(AVERAGEIFS(Base!$E$2:$E$1000,Base!$B$2:$B$1000,$A7,Base!$K$2:$K$1000,">="&Resumo!$B$3,Base!$K$2:$K$1000,"<="&Resumo!$B$4),"–") -> 1 | D7: Documentação 1 | E7: Alexandre 1 | F7: =COUNTIFS(Base!$B$2:$B$1000,$A7) -> 6 | G7: =AVERAGEIFS(Base!$E$2:$E$1000,Base!$B$2:$B$1000,$A7) -> 0.6 | H7: =COUNTIFS('Base monitorias'!$B$2:$B$41,$A7) -> 1 | I7: =IFERROR(AVERAGEIFS('Base monitorias'!$E$2:$E$41,'Base monitorias'!$B$2:$B$41,$A7),"sem monitoria") -> 59.5 | J7: 59.5 · 07/10 · Alexandre · feedback pendente | K7: =COUNTIFS('Base monitorias'!$B$2:$B$41,$A7,'Base monitorias'!$I$2:$I$41,"pendente") -> 1 | L7: Alta
A8: Gabriel Carneiro de Souza Tritto | B8: =COUNTIFS(Base!$B$2:$B$1000,$A8,Base!$K$2:$K$1000,">="&Resumo!$B$3,Base!$K$2:$K$1000,"<="&Resumo!$B$4) -> 16 | C8: =IFERROR(AVERAGEIFS(Base!$E$2:$E$1000,Base!$B$2:$B$1000,$A8,Base!$K$2:$K$1000,">="&Resumo!$B$3,Base!$K$2:$K$1000,"<="&Resumo!$B$4),"–") -> 0.728125 | D8: Rotina 11, Perdidos 3, Documentação 2 | E8: Pedro 14, Alexandre 2 | F8: =COUNTIFS(Base!$B$2:$B$1000,$A8) -> 16 | G8: =AVERAGEIFS(Base!$E$2:$E$1000,Base!$B$2:$B$1000,$A8) -> 0.728125 | H8: =COUNTIFS('Base monitorias'!$B$2:$B$41,$A8) -> 1 | I8: =IFERROR(AVERAGEIFS('Base monitorias'!$E$2:$E$41,'Base monitorias'!$B$2:$B$41,$A8),"sem monitoria") -> 56 | J8: 56.0 · 09/10 · Alexandre · feedback pendente | K8: =COUNTIFS('Base monitorias'!$B$2:$B$41,$A8,'Base monitorias'!$I$2:$I$41,"pendente") -> 1 | L8: Alta
A9: Alex Sandro Pacheoni | B9: =COUNTIFS(Base!$B$2:$B$1000,$A9,Base!$K$2:$K$1000,">="&Resumo!$B$3,Base!$K$2:$K$1000,"<="&Resumo!$B$4) -> 5 | C9: =IFERROR(AVERAGEIFS(Base!$E$2:$E$1000,Base!$B$2:$B$1000,$A9,Base!$K$2:$K$1000,">="&Resumo!$B$3,Base!$K$2:$K$1000,"<="&Resumo!$B$4),"–") -> 0.76 | D9: Rotina 5 | E9: Pedro 5 | F9: =COUNTIFS(Base!$B$2:$B$1000,$A9) -> 5 | G9: =AVERAGEIFS(Base!$E$2:$E$1000,Base!$B$2:$B$1000,$A9) -> 0.76 | H9: =COUNTIFS('Base monitorias'!$B$2:$B$41,$A9) -> 1 | I9: =IFERROR(AVERAGEIFS('Base monitorias'!$E$2:$E$41,'Base monitorias'!$B$2:$B$41,$A9),"sem monitoria") -> 66.5 | J9: 66.5 · 08/10 · Alexandre · feedback pendente | K9: =COUNTIFS('Base monitorias'!$B$2:$B$41,$A9,'Base monitorias'!$I$2:$I$41,"pendente") -> 1 | L9: Média
A10: Larissa Domingues Silva | B10: =COUNTIFS(Base!$B$2:$B$1000,$A10,Base!$K$2:$K$1000,">="&Resumo!$B$3,Base!$K$2:$K$1000,"<="&Resumo!$B$4) -> 1 | C10: =IFERROR(AVERAGEIFS(Base!$E$2:$E$1000,Base!$B$2:$B$1000,$A10,Base!$K$2:$K$1000,">="&Resumo!$B$3,Base!$K$2:$K$1000,"<="&Resumo!$B$4),"–") -> 0.8462 | D10: Vendas 1 | E10: Pedro 1 | F10: =COUNTIFS(Base!$B$2:$B$1000,$A10) -> 6 | G10: =AVERAGEIFS(Base!$E$2:$E$1000,Base!$B$2:$B$1000,$A10) -> 0.76923333 | H10: =COUNTIFS('Base monitorias'!$B$2:$B$41,$A10) -> 1 | I10: =IFERROR(AVERAGEIFS('Base monitorias'!$E$2:$E$41,'Base monitorias'!$B$2:$B$41,$A10),"sem monitoria") -> 81 | J10: 81.0 · 05/10 · Alexandre · feedback aplicado | K10: =COUNTIFS('Base monitorias'!$B$2:$B$41,$A10,'Base monitorias'!$I$2:$I$41,"pendente") -> 0 | L10: Média
A11: Adrielli Angela Maccio Moreto | B11: =COUNTIFS(Base!$B$2:$B$1000,$A11,Base!$K$2:$K$1000,">="&Resumo!$B$3,Base!$K$2:$K$1000,"<="&Resumo!$B$4) -> 17 | C11: =IFERROR(AVERAGEIFS(Base!$E$2:$E$1000,Base!$B$2:$B$1000,$A11,Base!$K$2:$K$1000,">="&Resumo!$B$3,Base!$K$2:$K$1000,"<="&Resumo!$B$4),"–") -> 0.78665294 | D11: Rotina 6, Status 5, Perdidos 5, Vendas 1 | E11: Alexandre 16, Pedro 1 | F11: =COUNTIFS(Base!$B$2:$B$1000,$A11) -> 19 | G11: =AVERAGEIFS(Base!$E$2:$E$1000,Base!$B$2:$B$1000,$A11) -> 0.79696316 | H11: =COUNTIFS('Base monitorias'!$B$2:$B$41,$A11) -> 1 | I11: =IFERROR(AVERAGEIFS('Base monitorias'!$E$2:$E$41,'Base monitorias'!$B$2:$B$41,$A11),"sem monitoria") -> 70 | J11: 70.0 · 02/10 · Alexandre · feedback aplicado | K11: =COUNTIFS('Base monitorias'!$B$2:$B$41,$A11,'Base monitorias'!$I$2:$I$41,"pendente") -> 0 | L11: Média
A12: Raquel Lima dos Anjos | B12: =COUNTIFS(Base!$B$2:$B$1000,$A12,Base!$K$2:$K$1000,">="&Resumo!$B$3,Base!$K$2:$K$1000,"<="&Resumo!$B$4) -> 7 | C12: =IFERROR(AVERAGEIFS(Base!$E$2:$E$1000,Base!$B$2:$B$1000,$A12,Base!$K$2:$K$1000,">="&Resumo!$B$3,Base!$K$2:$K$1000,"<="&Resumo!$B$4),"–") -> 0.79945714 | D12: Perdidos 5, Vendas 2 | E12: Pedro 7 | F12: =COUNTIFS(Base!$B$2:$B$1000,$A12) -> 7 | G12: =AVERAGEIFS(Base!$E$2:$E$1000,Base!$B$2:$B$1000,$A12) -> 0.79945714 | H12: =COUNTIFS('Base monitorias'!$B$2:$B$41,$A12) -> 2 | I12: =IFERROR(AVERAGEIFS('Base monitorias'!$E$2:$E$41,'Base monitorias'!$B$2:$B$41,$A12),"sem monitoria") -> 71.75 | J12: 68.5 · 07/10 · Alexandre · feedback pendente | K12: =COUNTIFS('Base monitorias'!$B$2:$B$41,$A12,'Base monitorias'!$I$2:$I$41,"pendente") -> 2 | L12: Média
A13: Ingrid Calderoni Martins | B13: =COUNTIFS(Base!$B$2:$B$1000,$A13,Base!$K$2:$K$1000,">="&Resumo!$B$3,Base!$K$2:$K$1000,"<="&Resumo!$B$4) -> 3 | C13: =IFERROR(AVERAGEIFS(Base!$E$2:$E$1000,Base!$B$2:$B$1000,$A13,Base!$K$2:$K$1000,">="&Resumo!$B$3,Base!$K$2:$K$1000,"<="&Resumo!$B$4),"–") -> 0.8 | D13: Rotina 2, Documentação 1 | E13: Pedro 2, Alexandre 1 | F13: =COUNTIFS(Base!$B$2:$B$1000,$A13) -> 3 | G13: =AVERAGEIFS(Base!$E$2:$E$1000,Base!$B$2:$B$1000,$A13) -> 0.8 | H13: =COUNTIFS('Base monitorias'!$B$2:$B$41,$A13) -> 0 | I13: =IFERROR(AVERAGEIFS('Base monitorias'!$E$2:$E$41,'Base monitorias'!$B$2:$B$41,$A13),"sem monitoria") -> sem monitoria | J13: nenhuma no mês | K13: =COUNTIFS('Base monitorias'!$B$2:$B$41,$A13,'Base monitorias'!$I$2:$I$41,"pendente") -> 0 | L13: Média
A14: Nélio Fernando de Souza Junior | B14: =COUNTIFS(Base!$B$2:$B$1000,$A14,Base!$K$2:$K$1000,">="&Resumo!$B$3,Base!$K$2:$K$1000,"<="&Resumo!$B$4) -> 16 | C14: =IFERROR(AVERAGEIFS(Base!$E$2:$E$1000,Base!$B$2:$B$1000,$A14,Base!$K$2:$K$1000,">="&Resumo!$B$3,Base!$K$2:$K$1000,"<="&Resumo!$B$4),"–") -> 0.861775 | D14: Status 7, Perdidos 5, Documentação 2, Vendas 2 | E14: Alexandre 8, Pedro 8 | F14: =COUNTIFS(Base!$B$2:$B$1000,$A14) -> 16 | G14: =AVERAGEIFS(Base!$E$2:$E$1000,Base!$B$2:$B$1000,$A14) -> 0.861775 | H14: =COUNTIFS('Base monitorias'!$B$2:$B$41,$A14) -> 2 | I14: =IFERROR(AVERAGEIFS('Base monitorias'!$E$2:$E$41,'Base monitorias'!$B$2:$B$41,$A14),"sem monitoria") -> 76.5 | J14: 70.5 · 06/10 · Alexandre · feedback aplicado | K14: =COUNTIFS('Base monitorias'!$B$2:$B$41,$A14,'Base monitorias'!$I$2:$I$41,"pendente") -> 0 | L14: Baixa
A15: Isabelly Rocha de Souza | B15: =COUNTIFS(Base!$B$2:$B$1000,$A15,Base!$K$2:$K$1000,">="&Resumo!$B$3,Base!$K$2:$K$1000,"<="&Resumo!$B$4) -> 17 | C15: =IFERROR(AVERAGEIFS(Base!$E$2:$E$1000,Base!$B$2:$B$1000,$A15,Base!$K$2:$K$1000,">="&Resumo!$B$3,Base!$K$2:$K$1000,"<="&Resumo!$B$4),"–") -> 0.9 | D15: Perdidos 6, Status 5, Rotina 5, Documentação 1 | E15: Alexandre 10, Pedro 7 | F15: =COUNTIFS(Base!$B$2:$B$1000,$A15) -> 19 | G15: =AVERAGEIFS(Base!$E$2:$E$1000,Base!$B$2:$B$1000,$A15) -> 0.89838421 | H15: =COUNTIFS('Base monitorias'!$B$2:$B$41,$A15) -> 1 | I15: =IFERROR(AVERAGEIFS('Base monitorias'!$E$2:$E$41,'Base monitorias'!$B$2:$B$41,$A15),"sem monitoria") -> 84 | J15: 84.0 · 02/10 · Alexandre · feedback aplicado | K15: =COUNTIFS('Base monitorias'!$B$2:$B$41,$A15,'Base monitorias'!$I$2:$I$41,"pendente") -> 0 | L15: Baixa
A16: Kethelyn Cristina Faria de Oliveira | B16: =COUNTIFS(Base!$B$2:$B$1000,$A16,Base!$K$2:$K$1000,">="&Resumo!$B$3,Base!$K$2:$K$1000,"<="&Resumo!$B$4) -> 7 | C16: =IFERROR(AVERAGEIFS(Base!$E$2:$E$1000,Base!$B$2:$B$1000,$A16,Base!$K$2:$K$1000,">="&Resumo!$B$3,Base!$K$2:$K$1000,"<="&Resumo!$B$4),"–") -> 0.91428571 | D16: Documentação 6, Rotina 1 | E16: Alexandre 5, Pedro 2 | F16: =COUNTIFS(Base!$B$2:$B$1000,$A16) -> 8 | G16: =AVERAGEIFS(Base!$E$2:$E$1000,Base!$B$2:$B$1000,$A16) -> 0.905775 | H16: =COUNTIFS('Base monitorias'!$B$2:$B$41,$A16) -> 1 | I16: =IFERROR(AVERAGEIFS('Base monitorias'!$E$2:$E$41,'Base monitorias'!$B$2:$B$41,$A16),"sem monitoria") -> 75 | J16: 75.0 · 02/10 · Alexandre · feedback aplicado | K16: =COUNTIFS('Base monitorias'!$B$2:$B$41,$A16,'Base monitorias'!$I$2:$I$41,"pendente") -> 0 | L16: Baixa
... A18: Joice Alice da Silva Sá | B18: =COUNTIFS(Base!$B$2:$B$1000,$A18,Base!$K$2:$K$1000,">="&Resumo!$B$3,Base!$K$2:$K$1000,"<="&Resumo!$B$4) -> 1 | C18: =IFERROR(AVERAGEIFS(Base!$E$2:$E$1000,Base!$B$2:$B$1000,$A18,Base!$K$2:$K$1000,">="&Resumo!$B$3,Base!$K$2:$K$1000,"<="&Resumo!$B$4),"–") -> 1 | D18: Documentação 1 | E18: Alexandre 1 | F18: =COUNTIFS(Base!$B$2:$B$1000,$A18) -> 1 | G18: =AVERAGEIFS(Base!$E$2:$E$1000,Base!$B$2:$B$1000,$A18) -> 1 | H18: =COUNTIFS('Base monitorias'!$B$2:$B$41,$A18) -> 1 | I18: =IFERROR(AVERAGEIFS('Base monitorias'!$E$2:$E$41,'Base monitorias'!$B$2:$B$41,$A18),"sem monitoria") -> 63.5 | J18: 63.5 · 09/10 · Alexandre · feedback pendente | K18: =COUNTIFS('Base monitorias'!$B$2:$B$41,$A18,'Base monitorias'!$I$2:$I$41,"pendente") -> 1 | L18: Alta
A19: Total / média | B19: =SUM(B5:B18) -> 112 | C19: =Resumo!C12 -> 0.80673125 | F19: =SUM(F5:F18) -> 137 | G19: =Resumo!E12 -> 0.78635693 | H19: =SUM(H5:H18) -> 15 | I19: =AVERAGEIFS('Base monitorias'!$E$2:$E$41,'Base monitorias'!$M$2:$M$41,"Sim") -> 69.2 | K19: =SUM(K5:K18) -> 7
A21: Todos os 14 closers tiveram auditoria na semana. Ingrid foi a única sem monitoria no mês. Fontes: auditorias (base detalhada) e monitorias (export Locus de 01–09/10).

Sheet Monitorias
A1: Resultado de monitoria — Time Tiago vs demais equipes (01–09/10)
A3: Indicador | B3: Time Tiago | C3: Demais equipes | D3: Todas (Locus: 40)
A4: Monitorias | B4: =COUNTIFS('Base monitorias'!$M$2:$M$41,"Sim") -> 15 | C4: =COUNTIFS('Base monitorias'!$M$2:$M$41,"Não") -> 25 | D4: =COUNTA('Base monitorias'!$B$2:$B$41) -> 40
A5: Nota média | B5: =AVERAGEIFS('Base monitorias'!$E$2:$E$41,'Base monitorias'!$M$2:$M$41,"Sim") -> 69.2 | C5: =AVERAGEIFS('Base monitorias'!$E$2:$E$41,'Base monitorias'!$M$2:$M$41,"Não") -> 84.6 | D5: =AVERAGE('Base monitorias'!$E$2:$E$41) -> 78.825
A6: Monitorias com nota <70 (crítico) | B6: =COUNTIFS('Base monitorias'!$M$2:$M$41,"Sim",'Base monitorias'!$E$2:$E$41,"<70") -> 7 | C6: =COUNTIFS('Base monitorias'!$M$2:$M$41,"Não",'Base monitorias'!$E$2:$E$41,"<70") -> 1 | D6: =COUNTIFS('Base monitorias'!$E$2:$E$41,"<70") -> 8
A7: Monitorias com nota ≥85 (bom) | B7: =COUNTIFS('Base monitorias'!$M$2:$M$41,"Sim",'Base monitorias'!$E$2:$E$41,">=85") -> 0 | C7: =COUNTIFS('Base monitorias'!$M$2:$M$41,"Não",'Base monitorias'!$E$2:$E$41,">=85") -> 15 | D7: =COUNTIFS('Base monitorias'!$E$2:$E$41,">=85") -> 15
A8: Feedbacks aplicados | B8: =COUNTIFS('Base monitorias'!$M$2:$M$41,"Sim",'Base monitorias'!$I$2:$I$41,"aplicado") -> 8 | C8: =COUNTIFS('Base monitorias'!$M$2:$M$41,"Não",'Base monitorias'!$I$2:$I$41,"aplicado") -> 20 | D8: =COUNTIFS('Base monitorias'!$I$2:$I$41,"aplicado") -> 28
A9: Feedbacks pendentes | B9: =COUNTIFS('Base monitorias'!$M$2:$M$41,"Sim",'Base monitorias'!$I$2:$I$41,"pendente") -> 7 | C9: =COUNTIFS('Base monitorias'!$M$2:$M$41,"Não",'Base monitorias'!$I$2:$I$41,"pendente") -> 5 | D9: =COUNTIFS('Base monitorias'!$I$2:$I$41,"pendente") -> 12
A10: % feedbacks aplicados | B10: =B8/B4 -> 0.53333333 | C10: =C8/C4 -> 0.8 | D10: =D8/D4 -> 0.7
A11: Erros críticos | B11: =COUNTIFS('Base monitorias'!$M$2:$M$41,"Sim",'Base monitorias'!$K$2:$K$41,"Sim") -> 0 | C11: =COUNTIFS('Base monitorias'!$M$2:$M$41,"Não",'Base monitorias'!$K$2:$K$41,"Sim") -> 0 | D11: =COUNTIFS('Base monitorias'!$K$2:$K$41,"Sim") -> 0
A13: Por monitor — monitorias do Time Tiago
A14: Monitor | B14: Monitorias (Tiago) | C14: Nota média (Tiago) | D14: Feedbacks pendentes (Tiago)
A15: Alexandre Gomes da Silva | B15: =COUNTIFS('Base monitorias'!$C$2:$C$41,$A15,'Base monitorias'!$M$2:$M$41,"Sim") -> 12 | C15: =IFERROR(AVERAGEIFS('Base monitorias'!$E$2:$E$41,'Base monitorias'!$C$2:$C$41,$A15,'Base monitorias'!$M$2:$M$41,"Sim"),"–") -> 68.75 | D15: =COUNTIFS('Base monitorias'!$C$2:$C$41,$A15,'Base monitorias'!$M$2:$M$41,"Sim",'Base monitorias'!$I$2:$I$41,"pendente") -> 5
A16: Pedro Henrique de Castro | B16: =COUNTIFS('Base monitorias'!$C$2:$C$41,$A16,'Base monitorias'!$M$2:$M$41,"Sim") -> 3 | C16: =IFERROR(AVERAGEIFS('Base monitorias'!$E$2:$E$41,'Base monitorias'!$C$2:$C$41,$A16,'Base monitorias'!$M$2:$M$41,"Sim"),"–") -> 71 | D16: =COUNTIFS('Base monitorias'!$C$2:$C$41,$A16,'Base monitorias'!$M$2:$M$41,"Sim",'Base monitorias'!$I$2:$I$41,"pendente") -> 2
A17: Anderson Nascimento Domingos | B17: =COUNTIFS('Base monitorias'!$C$2:$C$41,$A17,'Base monitorias'!$M$2:$M$41,"Sim") -> 0 | C17: =IFERROR(AVERAGEIFS('Base monitorias'!$E$2:$E$41,'Base monitorias'!$C$2:$C$41,$A17,'Base monitorias'!$M$2:$M$41,"Sim"),"–") -> – | D17: =COUNTIFS('Base monitorias'!$C$2:$C$41,$A17,'Base monitorias'!$M$2:$M$41,"Sim",'Base monitorias'!$I$2:$I$41,"pendente") -> 0
A18: Guilherme Ribeiro da Silva | B18: =COUNTIFS('Base monitorias'!$C$2:$C$41,$A18,'Base monitorias'!$M$2:$M$41,"Sim") -> 0 | C18: =IFERROR(AVERAGEIFS('Base monitorias'!$E$2:$E$41,'Base monitorias'!$C$2:$C$41,$A18,'Base monitorias'!$M$2:$M$41,"Sim"),"–") -> – | D18: =COUNTIFS('Base monitorias'!$C$2:$C$41,$A18,'Base monitorias'!$M$2:$M$41,"Sim",'Base monitorias'!$I$2:$I$41,"pendente") -> 0
A19: Alexandre e Pedro monitoraram quase só o time do Tiago; Anderson e Guilherme, os demais. A diferença de nota pode misturar efeito de equipe e de monitor.
A21: Feedbacks pendentes do Time Tiago
A22: Closer | B22: Nota | C22: Data | D22: Monitor | E22: Envio
A23: Andreza Aparecida Sousa Costa | B23: 55.5 | C23: 46300 | D23: Pedro Henrique de Castro | E23: Não enviado
A24: Gabriel Carneiro de Souza Tritto | B24: 56 | C24: 46304 | D24: Alexandre Gomes da Silva | E24: Oficial
A25: Otavio Augusto Soares Greghi | B25: 59.5 | C25: 46302 | D25: Alexandre Gomes da Silva | E25: Oficial
A26: Joice Alice da Silva Sá | B26: 63.5 | C26: 46304 | D26: Alexandre Gomes da Silva | E26: Oficial
A27: Alex Sandro Pacheoni | B27: 66.5 | C27: 46303 | D27: Alexandre Gomes da Silva | E27: Oficial
A28: Raquel Lima dos Anjos | B28: 68.5 | C28: 46302 | D28: Alexandre Gomes da Silva | E28: Oficial
A29: Raquel Lima dos Anjos | B29: 75 | C29: 46296 | D29: Pedro Henrique de Castro | E29: Não enviado
A31: Visão geral do Locus (todas as equipes, out/26)
A32: Monitorias realizadas | B32: 40 (ritmo esperado: 70 de 210 no mês)
A33: Nota média | B33: 78,8 — regular (−3,9 pts vs 1–9 set)
A34: Erros críticos | B34: 0
A35: Adesão a feedbacks | B35: 70% (28 de 40; 12 pendentes; −30 p.p. vs 1–9 set)
A36: Cobertura de ciclos | B36: 24,4% (41 de 168). Tiago: 15/60 — 45 pendentes, o maior backlog entre os supervisores
A37: Nota por ciclo | B37: C1 77,2 (31 monitorias) · C2 86,0 (7) · C3 — (0) · C4 78,8 (2)
A38: Nota por quartil de eficiência | B38: Q2 88,0 · Q3 82,4 · Q4 77,2 (30 das 40 no Q4)
A39: Produção dos monitores | B39: Alexandre 13/84 · Guilherme 12/63 · Anderson 12/63 · Pedro 3 (sem meta)
A41: Quartil: Q4 = menor eficiência. Nota por ciclo e quartil lidos como valor · nº de monitorias · rótulo.

Sheet Recorrentes
A1: Itens mais recorrentes — auditorias × monitorias
A3: A. Auditorias — equipe do Tiago (cada closer sobre o próprio volume; ver aba 'Ranking de itens')
A4: Item | B4: Formulário | C4: Conf. média dos closers | D4: Closers que falharam / com resposta
A5: ='Ranking de itens'!A6 -> Alertou sobre alterações no plano | B5: ='Ranking de itens'!B6 -> Vendas | C5: ='Ranking de itens'!C6 -> 0.11111111 | D5: ='Ranking de itens'!E6&" de "&'Ranking de itens'!D6 -> 6 de 6
A6: ='Ranking de itens'!A7 -> Indicação de lead | B6: ='Ranking de itens'!B7 -> Vendas | C6: ='Ranking de itens'!C7 -> 0.16666667 | D6: ='Ranking de itens'!E7&" de "&'Ranking de itens'!D7 -> 3 de 3
A7: ='Ranking de itens'!A9 -> Realizou a cadência | B7: ='Ranking de itens'!B9 -> Perdidos | C7: ='Ranking de itens'!C9 -> 0.45 | D7: ='Ranking de itens'!E9&" de "&'Ranking de itens'!D9 -> 7 de 7
A8: ='Ranking de itens'!A10 -> Rotina | B8: ='Ranking de itens'!B10 -> Rotina | C8: ='Ranking de itens'!C10 -> 0.54449495 | D8: ='Ranking de itens'!E10&" de "&'Ranking de itens'!D10 -> 8 de 10
A9: ='Ranking de itens'!A11 -> Seguiu o processo de argumentação | B9: ='Ranking de itens'!B11 -> Perdidos | C9: ='Ranking de itens'!C11 -> 0.57380952 | D9: ='Ranking de itens'!E11&" de "&'Ranking de itens'!D11 -> 7 de 7
A10: ='Ranking de itens'!A12 -> Motivo correto | B10: ='Ranking de itens'!B12 -> Perdidos | C10: ='Ranking de itens'!C12 -> 0.57777778 | D10: ='Ranking de itens'!E12&" de "&'Ranking de itens'!D12 -> 5 de 6
A11: ='Ranking de itens'!A13 -> CRM (sistema) | B11: ='Ranking de itens'!B13 -> Rotina | C11: ='Ranking de itens'!C13 -> 0.62295455 | D11: ='Ranking de itens'!E13&" de "&'Ranking de itens'!D13 -> 10 de 10
A12: ='Ranking de itens'!A14 -> Informou as regras de condutor adicional | B12: ='Ranking de itens'!B14 -> Vendas | C12: ='Ranking de itens'!C14 -> 0.80952381 | D12: ='Ranking de itens'!E14&" de "&'Ranking de itens'!D14 -> 3 de 7
A14: Só itens com 3+ closers respondendo (itens com 1–2 respostas ficam na aba Ranking de itens).
A16: B. Monitorias — Locus, out/26, todas as equipes (valores digitados da tela)
A17: Critério com mais erro | B17: Ocorrências | C17: % (como no Locus) | D17: Critério mais forte | E17: Ocorrências | F17: %
A18: Sondagem | B18: 7 | C18: 0.167 | D18: Atendimento personalizado | E18: 34 | F18: 0.063
A19: Clareza e reforço | B19: 6 | C19: 0.143 | D19: Motivo do contato | E19: 33 | F19: 0.061
A20: Registro no CRM | B20: 5 | C20: 0.119 | D20: Gradatividade condicional | E20: 31 | F20: 0.058
A21: Argumentação | B21: 5 | C21: 0.119 | D21: Entusiasmo | E21: 31 | F21: 0.058
A22: Escuta ativa | B22: 3 | C22: 0.071 | D22: Apresentação | E22: 31 | F22: 0.058
A23: Esses números do Locus são do mês inteiro e de todas as equipes (não filtrados por Tiago). Falta clicar em 'quem errou' filtrando o Time Tiago.
A25: C. Cruzamento — o que se repete nas duas bases
A26: Tema | B26: Nas auditorias | C26: Nas monitorias | D26: Leitura
A27: Argumentação | B27: Seguiu o processo de argumentação: 57% de média; falhou em 7 de 7 closers que fizeram Perdidos | C27: Argumentação: 5 ocorrências (11,9%) | D27: Aparece nas DUAS bases → prioridade 1 de treinamento.
A28: CRM (sistema) | B28: CRM (Status tag + Registro na interna + Tarefa): 62% de média; falhou em 10 de 10 closers que fizeram Rotina | C28: Registro no CRM: 5 ocorrências (11,9%) | D28: Aparece nas DUAS bases → rotina de conferir o CRM ao fechar cada lead.
A29: Cadência / follow-up | B29: Realizou a cadência: 45%; 7 de 7 closers falharam (Adriano 0/5) | C29: — (não é critério da monitoria) | D29: Só nas auditorias, mas é o item mais crítico dos Perdidos.
A30: Rotina (contato por lead) | B30: Item Rotina: 54%; 8 de 10 closers falharam | C30: — | D30: Sugestão: analisar o registro das ligações (tentativas por lead e efetivas ≥1:30). Ver aba 'Tentativas por lead'.
A31: Sondagem, clareza e reforço, escuta ativa | B31: — | C31: Sondagem 7 · Clareza e reforço 6 · Escuta ativa 3 | D31: Só nas monitorias (qualidade da conversa). Ver quem errou no Time Tiago no Locus.
A32: Vendas | B32: Alertou sobre alterações no plano 11% (6 de 6); Indicação de lead 17% (3 de 3) | C32: — | D32: Só nas auditorias; poucas respostas por closer (1 a 3).

Sheet Plano de ação
A1: Sugestões de acompanhamento — próxima semana (13 a 16/10; 12/10 é feriado)
A2: São sugestões, sem compromisso de prazo ou meta. Ajuste conforme a rotina do time.
A4: Prioridade | B4: Quem | C4: Situação (dados do período) | D4: Sugestão de acompanhamento
A5: Alta | B5: Adriano Robson Gomes | C5: Auditoria 57,1% (14); monitoria 52,0. Cadência 0/5, Motivo correto 4/5 com falha, CRM (sistema) 9/24 com falha. 4,1% das ligações efetivas (05–09/10). | D5: Conversa individual sobre cadência e uso do CRM; olhar o registro das ligações (tentativas por lead e efetivas ≥1:30); mais auditorias de Perdidos e Rotina.
A6: Alta | B6: Andreza Aparecida Sousa Costa | C6: Auditoria 50% (4, todas Perdidos); monitoria 55,5 com feedback ainda a enviar. Cadência 3/4, argumentação 2/3. | D6: Enviar o feedback da monitoria de 05/10 e conversar sobre cadência e argumentação; mais auditorias de Perdidos.
A7: Alta | B7: Otavio Augusto Soares Greghi | C7: Auditoria 60% (6; 5 de Rotina a 52%); monitoria 59,5 com feedback pendente. CRM (sistema) 9/15 com falha. | D7: Aplicar o feedback pendente; combinar a rotina de conferir o CRM (tag, tarefa e registro na interna) em cada lead; mais auditorias de Rotina.
A8: Alta | B8: Gabriel Carneiro de Souza Tritto | C8: Auditoria 72,8% (16; Rotina 67,3%, item Rotina 8/11); monitoria 56,0 com feedback pendente. 51 ligações em 5 dias. | D8: Aplicar o feedback pendente; revisar o fluxo de Rotina e olhar o registro das ligações; mais auditorias de Rotina.
A9: Alta | B9: Joice Alice da Silva Sá | C9: Closer nova; ficou em casa nesta semana, o que dificultou o acompanhamento. Só 1 auditoria (100%), mas monitoria 63,5 com feedback pendente. | D9: Acompanhar mais de perto: aplicar o feedback pendente e fazer mais auditorias para formar amostra.
A10: Média | B10: Alex Sandro Pacheoni | C10: Auditoria 76% (5 Rotina); monitoria 66,5 com feedback pendente. CRM (sistema) 4/15 com falha; item Rotina 2/5. | D10: Aplicar o feedback; reforçar o preenchimento do CRM; validar o usuário duplicado (alexpacheoni-remalho).
A11: Média | B11: Raquel Lima dos Anjos | C11: Auditoria 79,9% (7); monitorias 68,5 (feedback pendente) e 75,0 (feedback a enviar, ciclo 4). Cadência 3/5. | D11: Enviar o feedback do ciclo 4 e aplicar o de 07/10; foco em cadência.
A12: Média | B12: Larissa Domingues Silva | C12: Auditoria 76,9% (6); monitoria 81,0 aplicada. CRM (sistema) 4/12 com falha. Enviou 0,23 msg por msg recebida (2.565 recebidas). | D12: Reforçar o CRM; conferir o volume de mensagens recebidas sem resposta.
A13: Média | B13: Adrielli Angela Maccio Moreto | C13: Auditoria 79,7% (19); monitoria 70,0 aplicada. Argumentação 3/5, cadência 3/5, CRM (sistema) 5/12 com falha. | D13: Exercício de argumentação e cadência (o mesmo do time); mais auditorias de Perdidos.
A14: Média | B14: Ingrid Calderoni Martins | C14: Auditoria 80% (3); nenhuma monitoria no mês (ciclo não iniciado). CRM (sistema) 2/6 com falha. | D14: Incluir na próxima rodada de monitorias.
A15: Baixa | B15: Nélio, Isabelly, Kethelyn, Isadora | C15: Auditoria 86–91%; monitorias 70,5–84. Alertou sobre alterações no plano e Indicação de lead (Nélio 2/2, Isabelly 2/2 no primeiro). Isadora: Rotina 2/2. | D15: Acompanhar; feedback pontual em Vendas e Rotina.
... A24: Processo | B24: Dados e relatórios | C24: Pendências de nome/usuário no WhatsApp (Isabelly, Alex, 'opm...') e itens de monitoria sem filtro por equipe. | D24: Validar as pendências e exportar 'quem errou' por critério filtrado no Time Tiago.

Sheet Destaques WhatsApp
A1: Destaques de WhatsApp — Time Tiago (ranking)
A2: Mensagens: 25/09–09/10 (relatório do Connect). Ligações: 05–09/10 (relatório analítico). Percentuais sobre o volume do próprio closer. Dados em validação (Isabelly sem mensagens; Alex com 2 usuários).
A4: # | B4: Mais mensagens recebidas | C4: Recebidas | D4: Conversas | F4: # | G4: Mais áudios enviados | H4: Áudios enviados | I4: % das msgs enviadas | K4: # | L4: Mais ligações efetivas (≥1:30, 05–09/10) | M4: Efetivas | N4: % das ligações do closer
A5: 1 | B5: Larissa Domingues Silva | C5: =INDEX('WhatsApp msgs'!$B$4:$B$17,MATCH($B5,'WhatsApp msgs'!$A$4:$A$17,0)) -> 2565 | D5: =INDEX('WhatsApp msgs'!$D$4:$D$17,MATCH($B5,'WhatsApp msgs'!$A$4:$A$17,0)) -> 80 | F5: 1 | G5: Nélio Fernando de Souza Junior | H5: =INDEX('WhatsApp msgs'!$H$4:$H$17,MATCH($G5,'WhatsApp msgs'!$A$4:$A$17,0)) -> 589 | I5: =INDEX('WhatsApp msgs'!$H$4:$H$17,MATCH($G5,'WhatsApp msgs'!$A$4:$A$17,0))/INDEX('WhatsApp msgs'!$C$4:$C$17,MATCH($G5,'WhatsApp msgs'!$A$4:$A$17,0)) -> 0.64512596 | K5: 1 | L5: Raquel Lima dos Anjos | M5: =INDEX(Ligações!$C$4:$C$17,MATCH($L5,Ligações!$A$4:$A$17,0)) -> 37 | N5: =INDEX(Ligações!$D$4:$D$17,MATCH($L5,Ligações!$A$4:$A$17,0)) -> 0.14624506
A6: 2 | B6: Adrielli Angela Maccio Moreto | C6: =INDEX('WhatsApp msgs'!$B$4:$B$17,MATCH($B6,'WhatsApp msgs'!$A$4:$A$17,0)) -> 1455 | D6: =INDEX('WhatsApp msgs'!$D$4:$D$17,MATCH($B6,'WhatsApp msgs'!$A$4:$A$17,0)) -> 122 | F6: 2 | G6: Gabriel Carneiro de Souza Tritto | H6: =INDEX('WhatsApp msgs'!$H$4:$H$17,MATCH($G6,'WhatsApp msgs'!$A$4:$A$17,0)) -> 539 | I6: =INDEX('WhatsApp msgs'!$H$4:$H$17,MATCH($G6,'WhatsApp msgs'!$A$4:$A$17,0))/INDEX('WhatsApp msgs'!$C$4:$C$17,MATCH($G6,'WhatsApp msgs'!$A$4:$A$17,0)) -> 0.69638243 | K6: 2 | L6: Kethelyn Cristina Faria de Oliveira | M6: =INDEX(Ligações!$C$4:$C$17,MATCH($L6,Ligações!$A$4:$A$17,0)) -> 34 | N6: =INDEX(Ligações!$D$4:$D$17,MATCH($L6,Ligações!$A$4:$A$17,0)) -> 0.10897436
A7: 3 | B7: Nélio Fernando de Souza Junior | C7: =INDEX('WhatsApp msgs'!$B$4:$B$17,MATCH($B7,'WhatsApp msgs'!$A$4:$A$17,0)) -> 905 | D7: =INDEX('WhatsApp msgs'!$D$4:$D$17,MATCH($B7,'WhatsApp msgs'!$A$4:$A$17,0)) -> 65 | F7: 3 | G7: Adrielli Angela Maccio Moreto | H7: =INDEX('WhatsApp msgs'!$H$4:$H$17,MATCH($G7,'WhatsApp msgs'!$A$4:$A$17,0)) -> 462 | I7: =INDEX('WhatsApp msgs'!$H$4:$H$17,MATCH($G7,'WhatsApp msgs'!$A$4:$A$17,0))/INDEX('WhatsApp msgs'!$C$4:$C$17,MATCH($G7,'WhatsApp msgs'!$A$4:$A$17,0)) -> 0.35053111 | K7: 3 | L7: Adrielli Angela Maccio Moreto | M7: =INDEX(Ligações!$C$4:$C$17,MATCH($L7,Ligações!$A$4:$A$17,0)) -> 25 | N7: =INDEX(Ligações!$D$4:$D$17,MATCH($L7,Ligações!$A$4:$A$17,0)) -> 0.10729614
A8: 4 | B8: Gabriel Carneiro de Souza Tritto | C8: =INDEX('WhatsApp msgs'!$B$4:$B$17,MATCH($B8,'WhatsApp msgs'!$A$4:$A$17,0)) -> 857 | D8: =INDEX('WhatsApp msgs'!$D$4:$D$17,MATCH($B8,'WhatsApp msgs'!$A$4:$A$17,0)) -> 34 | F8: 4 | G8: Kethelyn Cristina Faria de Oliveira | H8: =INDEX('WhatsApp msgs'!$H$4:$H$17,MATCH($G8,'WhatsApp msgs'!$A$4:$A$17,0)) -> 386 | I8: =INDEX('WhatsApp msgs'!$H$4:$H$17,MATCH($G8,'WhatsApp msgs'!$A$4:$A$17,0))/INDEX('WhatsApp msgs'!$C$4:$C$17,MATCH($G8,'WhatsApp msgs'!$A$4:$A$17,0)) -> 0.43080357 | K8: 4 | L8: Ingrid Calderoni Martins | M8: =INDEX(Ligações!$C$4:$C$17,MATCH($L8,Ligações!$A$4:$A$17,0)) -> 21 | N8: =INDEX(Ligações!$D$4:$D$17,MATCH($L8,Ligações!$A$4:$A$17,0)) -> 0.23863636
A9: 5 | B9: Kethelyn Cristina Faria de Oliveira | C9: =INDEX('WhatsApp msgs'!$B$4:$B$17,MATCH($B9,'WhatsApp msgs'!$A$4:$A$17,0)) -> 840 | D9: =INDEX('WhatsApp msgs'!$D$4:$D$17,MATCH($B9,'WhatsApp msgs'!$A$4:$A$17,0)) -> 73 | F9: 5 | G9: Andreza Aparecida Sousa Costa | H9: =INDEX('WhatsApp msgs'!$H$4:$H$17,MATCH($G9,'WhatsApp msgs'!$A$4:$A$17,0)) -> 236 | I9: =INDEX('WhatsApp msgs'!$H$4:$H$17,MATCH($G9,'WhatsApp msgs'!$A$4:$A$17,0))/INDEX('WhatsApp msgs'!$C$4:$C$17,MATCH($G9,'WhatsApp msgs'!$A$4:$A$17,0)) -> 0.39597315 | K9: 5 | L9: Isabelly Rocha de Souza | M9: =INDEX(Ligações!$C$4:$C$17,MATCH($L9,Ligações!$A$4:$A$17,0)) -> 19 | N9: =INDEX(Ligações!$D$4:$D$17,MATCH($L9,Ligações!$A$4:$A$17,0)) -> 0.14285714

Sheet Resumo
A1: Consolidado da semana — Equipe do Tiago de Almeida Benatti
A3: Início da semana | B3: 46300 | C3: ← edite as datas e a meta; tudo recalcula
A4: Fim da semana | B4: 46304
A5: Meta de conformidade (alerta) | B5: 0.8
A7: Por avaliador
A8: Avaliador | B8: Auditorias na semana | C8: Conformidade na semana | D8: Auditorias no mês (01–09/10) | E8: Conformidade no mês
A9: Pedro Henrique de Castro | B9: =COUNTIFS(Base!$C$2:$C$138,A9,Base!$K$2:$K$138,">="&Resumo!$B$3,Base!$K$2:$K$138,"<="&Resumo!$B$4) -> 59 | C9: =IFERROR(AVERAGEIFS(Base!$E$2:$E$138,Base!$C$2:$C$138,A9,Base!$K$2:$K$138,">="&Resumo!$B$3,Base!$K$2:$K$138,"<="&Resumo!$B$4),"–") -> 0.6912 | D9: =COUNTIFS(Base!$C$2:$C$138,A9) -> 84 | E9: =IFERROR(AVERAGEIFS(Base!$E$2:$E$138,Base!$C$2:$C$138,A9),"–") -> 0.69235476
A10: Alexandre Gomes da Silva | B10: =COUNTIFS(Base!$C$2:$C$138,A10,Base!$K$2:$K$138,">="&Resumo!$B$3,Base!$K$2:$K$138,"<="&Resumo!$B$4) -> 53 | C10: =IFERROR(AVERAGEIFS(Base!$E$2:$E$138,Base!$C$2:$C$138,A10,Base!$K$2:$K$138,">="&Resumo!$B$3,Base!$K$2:$K$138,"<="&Resumo!$B$4),"–") -> 0.93534151 | D10: =COUNTIFS(Base!$C$2:$C$138,A10) -> 53 | E10: =IFERROR(AVERAGEIFS(Base!$E$2:$E$138,Base!$C$2:$C$138,A10),"–") -> 0.93534151
A11: Lilian Barbosa Bicudo Martins | B11: =COUNTIFS(Base!$C$2:$C$138,A11,Base!$K$2:$K$138,">="&Resumo!$B$3,Base!$K$2:$K$138,"<="&Resumo!$B$4) -> 0 | C11: =IFERROR(AVERAGEIFS(Base!$E$2:$E$138,Base!$C$2:$C$138,A11,Base!$K$2:$K$138,">="&Resumo!$B$3,Base!$K$2:$K$138,"<="&Resumo!$B$4),"–") -> – | D11: =COUNTIFS(Base!$C$2:$C$138,A11) -> 0 | E11: =IFERROR(AVERAGEIFS(Base!$E$2:$E$138,Base!$C$2:$C$138,A11),"–") -> –
A12: Total equipe do Tiago | B12: =COUNTIFS(Base!$K$2:$K$138,">="&Resumo!$B$3,Base!$K$2:$K$138,"<="&Resumo!$B$4) -> 112 | C12: =IFERROR(AVERAGEIFS(Base!$E$2:$E$138,Base!$K$2:$K$138,">="&Resumo!$B$3,Base!$K$2:$K$138,"<="&Resumo!$B$4),"–") -> 0.80673125 | D12: =COUNTA(Base!$C$2:$C$138) -> 137 | E12: =AVERAGE(Base!$E$2:$E$138) -> 0.78635693
A14: Por formulário
A15: Formulário | B15: Auditorias na semana | C15: Conformidade na semana | D15: Auditorias no mês | E15: Conformidade no mês
A16: Auditoria de Perdidos | B16: =COUNTIFS(Base!$D$2:$D$138,A16,Base!$K$2:$K$138,">="&Resumo!$B$3,Base!$K$2:$K$138,"<="&Resumo!$B$4) -> 33 | C16: =IFERROR(AVERAGEIFS(Base!$E$2:$E$138,Base!$D$2:$D$138,A16,Base!$K$2:$K$138,">="&Resumo!$B$3,Base!$K$2:$K$138,"<="&Resumo!$B$4),"–") -> 0.63636364 | D16: =COUNTIFS(Base!$D$2:$D$138,A16) -> 33 | E16: =IFERROR(AVERAGEIFS(Base!$E$2:$E$138,Base!$D$2:$D$138,A16),"–") -> 0.63636364
A17: Auditoria de Rotina | B17: =COUNTIFS(Base!$D$2:$D$138,A17,Base!$K$2:$K$138,">="&Resumo!$B$3,Base!$K$2:$K$138,"<="&Resumo!$B$4) -> 33 | C17: =IFERROR(AVERAGEIFS(Base!$E$2:$E$138,Base!$D$2:$D$138,A17,Base!$K$2:$K$138,">="&Resumo!$B$3,Base!$K$2:$K$138,"<="&Resumo!$B$4),"–") -> 0.73333333 | D17: =COUNTIFS(Base!$D$2:$D$138,A17) -> 50 | E17: =IFERROR(AVERAGEIFS(Base!$E$2:$E$138,Base!$D$2:$D$138,A17),"–") -> 0.7
A18: Auditoria de Documentação | B18: =COUNTIFS(Base!$D$2:$D$138,A18,Base!$K$2:$K$138,">="&Resumo!$B$3,Base!$K$2:$K$138,"<="&Resumo!$B$4) -> 16 | C18: =IFERROR(AVERAGEIFS(Base!$E$2:$E$138,Base!$D$2:$D$138,A18,Base!$K$2:$K$138,">="&Resumo!$B$3,Base!$K$2:$K$138,"<="&Resumo!$B$4),"–") -> 1 | D18: =COUNTIFS(Base!$D$2:$D$138,A18) -> 17 | E18: =IFERROR(AVERAGEIFS(Base!$E$2:$E$138,Base!$D$2:$D$138,A18),"–") -> 0.97058824
A19: Auditoria de Vendas | B19: =COUNTIFS(Base!$D$2:$D$138,A19,Base!$K$2:$K$138,">="&Resumo!$B$3,Base!$K$2:$K$138,"<="&Resumo!$B$4) -> 6 | C19: =IFERROR(AVERAGEIFS(Base!$E$2:$E$138,Base!$D$2:$D$138,A19,Base!$K$2:$K$138,">="&Resumo!$B$3,Base!$K$2:$K$138,"<="&Resumo!$B$4),"–") -> 0.85898333 | D19: =COUNTIFS(Base!$D$2:$D$138,A19) -> 13 | E19: =IFERROR(AVERAGEIFS(Base!$E$2:$E$138,Base!$D$2:$D$138,A19),"–") -> 0.86391538
A20: Auditoria de status | B20: =COUNTIFS(Base!$D$2:$D$138,A20,Base!$K$2:$K$138,">="&Resumo!$B$3,Base!$K$2:$K$138,"<="&Resumo!$B$4) -> 24 | C20: =IFERROR(AVERAGEIFS(Base!$E$2:$E$138,Base!$D$2:$D$138,A20,Base!$K$2:$K$138,">="&Resumo!$B$3,Base!$K$2:$K$138,"<="&Resumo!$B$4),"–") -> 1 | D20: =COUNTIFS(Base!$D$2:$D$138,A20) -> 24 | E20: =IFERROR(AVERAGEIFS(Base!$E$2:$E$138,Base!$D$2:$D$138,A20),"–") -> 1
A21: Auditoria de Estorno | B21: =COUNTIFS(Base!$D$2:$D$138,A21,Base!$K$2:$K$138,">="&Resumo!$B$3,Base!$K$2:$K$138,"<="&Resumo!$B$4) -> 0 | C21: =IFERROR(AVERAGEIFS(Base!$E$2:$E$138,Base!$D$2:$D$138,A21,Base!$K$2:$K$138,">="&Resumo!$B$3,Base!$K$2:$K$138,"<="&Resumo!$B$4),"–") -> – | D21: =COUNTIFS(Base!$D$2:$D$138,A21) -> 0 | E21: =IFERROR(AVERAGEIFS(Base!$E$2:$E$138,Base!$D$2:$D$138,A21),"–") -> –
A23: Observações
A24: • Escopo: avaliados cujo supervisor é Tiago de Almeida Benatti (14 pessoas, arquivo 'Pessoas com auditoria'); 137 auditorias em 01–09/10.
A25: • Conformidade = média simples das conformidades de cada auditoria (mesmo critério do sistema; bate com os relatórios por monitor e por formulário).
A26: • Lilian fez 1 auditoria no período (Talita Lacerda, Localiza, supervisora Amanda) — nenhuma na equipe do Tiago.
A27: • A base traz só a conformidade total de cada auditoria, não as respostas item a item do checklist; não dá para detalhar por pergunta.
A28: • Dia 04/10 (domingo) tem 11 auditorias do Pedro; ficam fora da 'semana' 05–09/10 e entram só no acumulado do mês.

Sheet Visão closer
A1: Visão por closer — qualidade (auditoria) × atividade (ligações e mensagens)
A3: Closer | B3: Aud. mês | C3: Conf. mês | D3: Pior item do checklist | E3: Ligações (05–09/10) | F3: % efetiva (05–09/10) | G3: Msgs enviadas (25/09–09/10) | H3: Conversas (25/09–09/10)
A4: Andreza Aparecida Sousa Costa | B4: =COUNTIFS(Base!$B$2:$B$1000,$A4) -> 4 | C4: =AVERAGEIFS(Base!$E$2:$E$1000,Base!$B$2:$B$1000,$A4) -> 0.5 | D4: Realizou a cadência (3/4); Seguiu o processo de argumentação (2/3) | E4: =INDEX(Ligações!$B$4:$B$17,MATCH($A4,Ligações!$A$4:$A$17,0)) -> 160 | F4: =INDEX(Ligações!$D$4:$D$17,MATCH($A4,Ligações!$A$4:$A$17,0)) -> 0.09375 | G4: =INDEX('WhatsApp msgs'!$C$4:$C$17,MATCH($A4,'WhatsApp msgs'!$A$4:$A$17,0)) -> 596 | H4: =INDEX('WhatsApp msgs'!$D$4:$D$17,MATCH($A4,'WhatsApp msgs'!$A$4:$A$17,0)) -> 62
A5: Adriano Robson Gomes | B5: =COUNTIFS(Base!$B$2:$B$1000,$A5) -> 14 | C5: =AVERAGEIFS(Base!$E$2:$E$1000,Base!$B$2:$B$1000,$A5) -> 0.57142857 | D5: Realizou a cadência (5/5); Motivo correto (4/5) | E5: =INDEX(Ligações!$B$4:$B$17,MATCH($A5,Ligações!$A$4:$A$17,0)) -> 222 | F5: =INDEX(Ligações!$D$4:$D$17,MATCH($A5,Ligações!$A$4:$A$17,0)) -> 0.040540541 | G5: =INDEX('WhatsApp msgs'!$C$4:$C$17,MATCH($A5,'WhatsApp msgs'!$A$4:$A$17,0)) -> 423 | H5: =INDEX('WhatsApp msgs'!$D$4:$D$17,MATCH($A5,'WhatsApp msgs'!$A$4:$A$17,0)) -> 40
A6: Otavio Augusto Soares Greghi | B6: =COUNTIFS(Base!$B$2:$B$1000,$A6) -> 6 | C6: =AVERAGEIFS(Base!$E$2:$E$1000,Base!$B$2:$B$1000,$A6) -> 0.6 | D6: CRM (sistema) (9/15); Rotina (2/5) | E6: =INDEX(Ligações!$B$4:$B$17,MATCH($A6,Ligações!$A$4:$A$17,0)) -> 53 | F6: =INDEX(Ligações!$D$4:$D$17,MATCH($A6,Ligações!$A$4:$A$17,0)) -> 0.22641509 | G6: =INDEX('WhatsApp msgs'!$C$4:$C$17,MATCH($A6,'WhatsApp msgs'!$A$4:$A$17,0)) -> 255 | H6: =INDEX('WhatsApp msgs'!$D$4:$D$17,MATCH($A6,'WhatsApp msgs'!$A$4:$A$17,0)) -> 27
A7: Gabriel Carneiro de Souza Tritto | B7: =COUNTIFS(Base!$B$2:$B$1000,$A7) -> 16 | C7: =AVERAGEIFS(Base!$E$2:$E$1000,Base!$B$2:$B$1000,$A7) -> 0.728125 | D7: Rotina (8/11); Seguiu o processo de argumentação (1/3) | E7: =INDEX(Ligações!$B$4:$B$17,MATCH($A7,Ligações!$A$4:$A$17,0)) -> 51 | F7: =INDEX(Ligações!$D$4:$D$17,MATCH($A7,Ligações!$A$4:$A$17,0)) -> 0.23529412 | G7: =INDEX('WhatsApp msgs'!$C$4:$C$17,MATCH($A7,'WhatsApp msgs'!$A$4:$A$17,0)) -> 774 | H7: =INDEX('WhatsApp msgs'!$D$4:$D$17,MATCH($A7,'WhatsApp msgs'!$A$4:$A$17,0)) -> 34
A8: Alex Sandro Pacheoni | B8: =COUNTIFS(Base!$B$2:$B$1000,$A8) -> 5 | C8: =AVERAGEIFS(Base!$E$2:$E$1000,Base!$B$2:$B$1000,$A8) -> 0.76 | D8: Rotina (2/5); CRM (sistema) (4/15) | E8: =INDEX(Ligações!$B$4:$B$17,MATCH($A8,Ligações!$A$4:$A$17,0)) -> 106 | F8: =INDEX(Ligações!$D$4:$D$17,MATCH($A8,Ligações!$A$4:$A$17,0)) -> 0.16037736 | G8: =INDEX('WhatsApp msgs'!$C$4:$C$17,MATCH($A8,'WhatsApp msgs'!$A$4:$A$17,0)) -> 37 | H8: =INDEX('WhatsApp msgs'!$D$4:$D$17,MATCH($A8,'WhatsApp msgs'!$A$4:$A$17,0)) -> 8
A9: Larissa Domingues Silva | B9: =COUNTIFS(Base!$B$2:$B$1000,$A9) -> 6 | C9: =AVERAGEIFS(Base!$E$2:$E$1000,Base!$B$2:$B$1000,$A9) -> 0.76923333 | D9: CRM (sistema) (4/12); Rotina (1/4) | E9: =INDEX(Ligações!$B$4:$B$17,MATCH($A9,Ligações!$A$4:$A$17,0)) -> 209 | F9: =INDEX(Ligações!$D$4:$D$17,MATCH($A9,Ligações!$A$4:$A$17,0)) -> 0.086124402 | G9: =INDEX('WhatsApp msgs'!$C$4:$C$17,MATCH($A9,'WhatsApp msgs'!$A$4:$A$17,0)) -> 587 | H9: =INDEX('WhatsApp msgs'!$D$4:$D$17,MATCH($A9,'WhatsApp msgs'!$A$4:$A$17,0)) -> 80
A10: Adrielli Angela Maccio Moreto | B10: =COUNTIFS(Base!$B$2:$B$1000,$A10) -> 19 | C10: =AVERAGEIFS(Base!$E$2:$E$1000,Base!$B$2:$B$1000,$A10) -> 0.79696316 | D10: Seguiu o processo de argumentação (3/5); Realizou a cadência (3/5) | E10: =INDEX(Ligações!$B$4:$B$17,MATCH($A10,Ligações!$A$4:$A$17,0)) -> 233 | F10: =INDEX(Ligações!$D$4:$D$17,MATCH($A10,Ligações!$A$4:$A$17,0)) -> 0.10729614 | G10: =INDEX('WhatsApp msgs'!$C$4:$C$17,MATCH($A10,'WhatsApp msgs'!$A$4:$A$17,0)) -> 1318 | H10: =INDEX('WhatsApp msgs'!$D$4:$D$17,MATCH($A10,'WhatsApp msgs'!$A$4:$A$17,0)) -> 122
A11: Raquel Lima dos Anjos | B11: =COUNTIFS(Base!$B$2:$B$1000,$A11) -> 7 | C11: =AVERAGEIFS(Base!$E$2:$E$1000,Base!$B$2:$B$1000,$A11) -> 0.79945714 | D11: Realizou a cadência (3/5); Seguiu o processo de argumentação (1/4) | E11: =INDEX(Ligações!$B$4:$B$17,MATCH($A11,Ligações!$A$4:$A$17,0)) -> 253 | F11: =INDEX(Ligações!$D$4:$D$17,MATCH($A11,Ligações!$A$4:$A$17,0)) -> 0.14624506 | G11: =INDEX('WhatsApp msgs'!$C$4:$C$17,MATCH($A11,'WhatsApp msgs'!$A$4:$A$17,0)) -> 333 | H11: =INDEX('WhatsApp msgs'!$D$4:$D$17,MATCH($A11,'WhatsApp msgs'!$A$4:$A$17,0)) -> 67
A12: Ingrid Calderoni Martins | B12: =COUNTIFS(Base!$B$2:$B$1000,$A12) -> 3 | C12: =AVERAGEIFS(Base!$E$2:$E$1000,Base!$B$2:$B$1000,$A12) -> 0.8 | D12: CRM (sistema) (2/6) | E12: =INDEX(Ligações!$B$4:$B$17,MATCH($A12,Ligações!$A$4:$A$17,0)) -> 88 | F12: =INDEX(Ligações!$D$4:$D$17,MATCH($A12,Ligações!$A$4:$A$17,0)) -> 0.23863636 | G12: =INDEX('WhatsApp msgs'!$C$4:$C$17,MATCH($A12,'WhatsApp msgs'!$A$4:$A$17,0)) -> 732 | H12: =INDEX('WhatsApp msgs'!$D$4:$D$17,MATCH($A12,'WhatsApp msgs'!$A$4:$A$17,0)) -> 29
A13: Nélio Fernando de Souza Junior | B13: =COUNTIFS(Base!$B$2:$B$1000,$A13) -> 16 | C13: =AVERAGEIFS(Base!$E$2:$E$1000,Base!$B$2:$B$1000,$A13) -> 0.861775 | D13: Seguiu o processo de argumentação (2/5); Realizou a cadência (2/5) | E13: =INDEX(Ligações!$B$4:$B$17,MATCH($A13,Ligações!$A$4:$A$17,0)) -> 170 | F13: =INDEX(Ligações!$D$4:$D$17,MATCH($A13,Ligações!$A$4:$A$17,0)) -> 0.094117647 | G13: =INDEX('WhatsApp msgs'!$C$4:$C$17,MATCH($A13,'WhatsApp msgs'!$A$4:$A$17,0)) -> 913 | H13: =INDEX('WhatsApp msgs'!$D$4:$D$17,MATCH($A13,'WhatsApp msgs'!$A$4:$A$17,0)) -> 65
A14: Isabelly Rocha de Souza | B14: =COUNTIFS(Base!$B$2:$B$1000,$A14) -> 19 | C14: =AVERAGEIFS(Base!$E$2:$E$1000,Base!$B$2:$B$1000,$A14) -> 0.89838421 | D14: Motivo correto (3/6); Seguiu o processo de argumentação (2/6) | E14: =INDEX(Ligações!$B$4:$B$17,MATCH($A14,Ligações!$A$4:$A$17,0)) -> 133 | F14: =INDEX(Ligações!$D$4:$D$17,MATCH($A14,Ligações!$A$4:$A$17,0)) -> 0.14285714 | G14: =INDEX('WhatsApp msgs'!$C$4:$C$17,MATCH($A14,'WhatsApp msgs'!$A$4:$A$17,0)) -> – | H14: =INDEX('WhatsApp msgs'!$D$4:$D$17,MATCH($A14,'WhatsApp msgs'!$A$4:$A$17,0)) -> –
A15: Kethelyn Cristina Faria de Oliveira | B15: =COUNTIFS(Base!$B$2:$B$1000,$A15) -> 8 | C15: =AVERAGEIFS(Base!$E$2:$E$1000,Base!$B$2:$B$1000,$A15) -> 0.905775 | D15: CRM (sistema) (2/2)*; Informou sobre a proibição de uso por apps de mobilidade e entrega (1/1)* | E15: =INDEX(Ligações!$B$4:$B$17,MATCH($A15,Ligações!$A$4:$A$17,0)) -> 312 | F15: =INDEX(Ligações!$D$4:$D$17,MATCH($A15,Ligações!$A$4:$A$17,0)) -> 0.10897436 | G15: =INDEX('WhatsApp msgs'!$C$4:$C$17,MATCH($A15,'WhatsApp msgs'!$A$4:$A$17,0)) -> 896 | H15: =INDEX('WhatsApp msgs'!$D$4:$D$17,MATCH($A15,'WhatsApp msgs'!$A$4:$A$17,0)) -> 73
... A17: Joice Alice da Silva Sá | B17: =COUNTIFS(Base!$B$2:$B$1000,$A17) -> 1 | C17: =AVERAGEIFS(Base!$E$2:$E$1000,Base!$B$2:$B$1000,$A17) -> 1 | D17: — | E17: =INDEX(Ligações!$B$4:$B$17,MATCH($A17,Ligações!$A$4:$A$17,0)) -> 56 | F17: =INDEX(Ligações!$D$4:$D$17,MATCH($A17,Ligações!$A$4:$A$17,0)) -> 0.23214286 | G17: =INDEX('WhatsApp msgs'!$C$4:$C$17,MATCH($A17,'WhatsApp msgs'!$A$4:$A$17,0)) -> 149 | H17: =INDEX('WhatsApp msgs'!$D$4:$D$17,MATCH($A17,'WhatsApp msgs'!$A$4:$A$17,0)) -> 10
A19: Isabelly: sem dados de mensagens (validar). Alex: msgs podem estar divididas em 2 usuários.

Sheet Matriz closer x item
A1: Conformidade por item do checklist — closers da equipe do Tiago (01–09/10)
A2: CRM (sistema) = Status tag + Registro na interna + Tarefa somados. Vermelho <70% · amarelo 70–89% · verde ≥90% · vazio = item sem resposta (ou fora do top 8 do Locus). Closers do mais crítico (topo) ao melhor.
D3: PERDIDOS | H3: ROTINA | K3: DOCUMENTAÇÃO | M3: VENDAS | Y3: STATUS
A4: Closer | B4: Aud. | C4: Conf. mês | D4: Seguiu o processo de argumentação | E4: Realizou a cadência | F4: Motivo correto | G4: Houve indicação | H4: Status fase | I4: Rotina | J4: CRM (sistema) | K4: Validou documentação | L4: Encaminhou documentação original | M4: Confirmou regularidade da CNH | N4: Informou as regras de condutor adicional | O4: Orientou sobre cadastro no site (Movida) ou prova de vida (Localiza) | P4: Informou das condições e cartão em nome do titular | Q4: Local de retirada | R4: Fez a ratificação do plano | S4: Explicou sobre o carro provisório | T4: Existe urgência real | U4: Informou sobre a proibição de uso por apps de mobilidade e entrega | V4: Alertou sobre alterações no plano | W4: Indicação de lead | X4: Solicitou documentos (RJ) | Y4: Status de aprovação correto
A5: Andreza Aparecida Sousa Costa | B5: =COUNTIFS(Base!$B$2:$B$1000,$A5) -> 4 | C5: =AVERAGEIFS(Base!$E$2:$E$1000,Base!$B$2:$B$1000,$A5) -> 0.5 | D5: =IF(SUMIFS('Itens (Locus)'!$E$3:$E$127,'Itens (Locus)'!$A$3:$A$127,$A5,'Itens (Locus)'!$C$3:$C$127,D$4)=0,"",1-SUMIFS('Itens (Locus)'!$D$3:$D$127,'Itens (Locus)'!$A$3:$A$127,$A5,'Itens (Locus)'!$C$3:$C$127,D$4)/SUMIFS('Itens (Locus)'!$E$3:$E$127,'Itens (Locus)'!$A$3:$A$127,$A5,'Itens (Locus)'!$C$3:$C$127,D$4)) -> 0.33333333 | E5: =IF(SUMIFS('Itens (Locus)'!$E$3:$E$127,'Itens (Locus)'!$A$3:$A$127,$A5,'Itens (Locus)'!$C$3:$C$127,E$4)=0,"",1-SUMIFS('Itens (Locus)'!$D$3:$D$127,'Itens (Locus)'!$A$3:$A$127,$A5,'Itens (Locus)'!$C$3:$C$127,E$4)/SUMIFS('Itens (Locus)'!$E$3:$E$127,'Itens (Locus)'!$A$3:$A$127,$A5,'Itens (Locus)'!$C$3:$C$127,E$4)) -> 0.25 | F5: =IF(SUMIFS('Itens (Locus)'!$E$3:$E$127,'Itens (Locus)'!$A$3:$A$127,$A5,'Itens (Locus)'!$C$3:$C$127,F$4)=0,"",1-SUMIFS('Itens (Locus)'!$D$3:$D$127,'Itens (Locus)'!$A$3:$A$127,$A5,'Itens (Locus)'!$C$3:$C$127,F$4)/SUMIFS('Itens (Locus)'!$E$3:$E$127,'Itens (Locus)'!$A$3:$A$127,$A5,'Itens (Locus)'!$C$3:$C$127,F$4)) -> 0.5 | G5: =IF(SUMIFS('Itens (Locus)'!$E$3:$E$127,'Itens (Locus)'!$A$3:$A$127,$A5,'Itens (Locus)'!$C$3:$C$127,G$4)=0,"",1-SUMIFS('Itens (Locus)'!$D$3:$D$127,'Itens (Locus)'!$A$3:$A$127,$A5,'Itens (Locus)'!$C$3:$C$127,G$4)/SUMIFS('Itens (Locus)'!$E$3:$E$127,'Itens (Locus)'!$A$3:$A$127,$A5,'Itens (Locus)'!$C$3:$C$127,G$4)) -> 0.75 | H5: =IF(SUMIFS('Itens (Locus)'!$E$3:$E$127,'Itens (Locus)'!$A$3:$A$127,$A5,'Itens (Locus)'!$C$3:$C$127,H$4)=0,"",1-SUMIFS('Itens (Locus)'!$D$3:$D$127,'Itens (Locus)'!$A$3:$A$127,$A5,'Itens (Locus)'!$C$3:$C$127,H$4)/SUMIFS('Itens (Locus)'!$E$3:$E$127,'Itens (Locus)'!$A$3:$A$127,$A5,'Itens (Locus)'!$C$3:$C$127,H$4)) | I5: =IF(SUMIFS('Itens (Locus)'!$E$3:$E$127,'Itens (Locus)'!$A$3:$A$127,$A5,'Itens (Locus)'!$C$3:$C$127,I$4)=0,"",1-SUMIFS('Itens (Locus)'!$D$3:$D$127,'Itens (Locus)'!$A$3:$A$127,$A5,'Itens (Locus)'!$C$3:$C$127,I$4)/SUMIFS('Itens (Locus)'!$E$3:$E$127,'Itens (Locus)'!$A$3:$A$127,$A5,'Itens (Locus)'!$C$3:$C$127,I$4)) | J5: =IF(SUMIFS('Itens (Locus)'!$E$3:$E$127,'Itens (Locus)'!$A$3:$A$127,$A5,'Itens (Locus)'!$C$3:$C$127,J$4)=0,"",1-SUMIFS('Itens (Locus)'!$D$3:$D$127,'Itens (Locus)'!$A$3:$A$127,$A5,'Itens (Locus)'!$C$3:$C$127,J$4)/SUMIFS('Itens (Locus)'!$E$3:$E$127,'Itens (Locus)'!$A$3:$A$127,$A5,'Itens (Locus)'!$C$3:$C$127,J$4)) | K5: =IF(SUMIFS('Itens (Locus)'!$E$3:$E$127,'Itens (Locus)'!$A$3:$A$127,$A5,'Itens (Locus)'!$C$3:$C$127,K$4)=0,"",1-SUMIFS('Itens (Locus)'!$D$3:$D$127,'Itens (Locus)'!$A$3:$A$127,$A5,'Itens (Locus)'!$C$3:$C$127,K$4)/SUMIFS('Itens (Locus)'!$E$3:$E$127,'Itens (Locus)'!$A$3:$A$127,$A5,'Itens (Locus)'!$C$3:$C$127,K$4)) | ... Y5: =IF(SUMIFS('Itens (Locus)'!$E$3:$E$127,'Itens (Locus)'!$A$3:$A$127,$A5,'Itens (Locus)'!$C$3:$C$127,Y$4)=0,"",1-SUMIFS('Itens (Locus)'!$D$3:$D$127,'Itens (Locus)'!$A$3:$A$127,$A5,'Itens (Locus)'!$C$3:$C$127,Y$4)/SUMIFS('Itens (Locus)'!$E$3:$E$127,'Itens (Locus)'!$A$3:$A$127,$A5,'Itens (Locus)'!$C$3:$C$127,Y$4))
A6: Adriano Robson Gomes | B6: =COUNTIFS(Base!$B$2:$B$1000,$A6) -> 14 | C6: =AVERAGEIFS(Base!$E$2:$E$1000,Base!$B$2:$B$1000,$A6) -> 0.57142857 | D6: =IF(SUMIFS('Itens (Locus)'!$E$3:$E$127,'Itens (Locus)'!$A$3:$A$127,$A6,'Itens (Locus)'!$C$3:$C$127,D$4)=0,"",1-SUMIFS('Itens (Locus)'!$D$3:$D$127,'Itens (Locus)'!$A$3:$A$127,$A6,'Itens (Locus)'!$C$3:$C$127,D$4)/SUMIFS('Itens (Locus)'!$E$3:$E$127,'Itens (Locus)'!$A$3:$A$127,$A6,'Itens (Locus)'!$C$3:$C$127,D$4)) -> 0.6 | E6: =IF(SUMIFS('Itens (Locus)'!$E$3:$E$127,'Itens (Locus)'!$A$3:$A$127,$A6,'Itens (Locus)'!$C$3:$C$127,E$4)=0,"",1-SUMIFS('Itens (Locus)'!$D$3:$D$127,'Itens (Locus)'!$A$3:$A$127,$A6,'Itens (Locus)'!$C$3:$C$127,E$4)/SUMIFS('Itens (Locus)'!$E$3:$E$127,'Itens (Locus)'!$A$3:$A$127,$A6,'Itens (Locus)'!$C$3:$C$127,E$4)) -> 0 | F6: =IF(SUMIFS('Itens (Locus)'!$E$3:$E$127,'Itens (Locus)'!$A$3:$A$127,$A6,'Itens (Locus)'!$C$3:$C$127,F$4)=0,"",1-SUMIFS('Itens (Locus)'!$D$3:$D$127,'Itens (Locus)'!$A$3:$A$127,$A6,'Itens (Locus)'!$C$3:$C$127,F$4)/SUMIFS('Itens (Locus)'!$E$3:$E$127,'Itens (Locus)'!$A$3:$A$127,$A6,'Itens (Locus)'!$C$3:$C$127,F$4)) -> 0.2 | G6: =IF(SUMIFS('Itens (Locus)'!$E$3:$E$127,'Itens (Locus)'!$A$3:$A$127,$A6,'Itens (Locus)'!$C$3:$C$127,G$4)=0,"",1-SUMIFS('Itens (Locus)'!$D$3:$D$127,'Itens (Locus)'!$A$3:$A$127,$A6,'Itens (Locus)'!$C$3:$C$127,G$4)/SUMIFS('Itens (Locus)'!$E$3:$E$127,'Itens (Locus)'!$A$3:$A$127,$A6,'Itens (Locus)'!$C$3:$C$127,G$4)) -> 0.8 | H6: =IF(SUMIFS('Itens (Locus)'!$E$3:$E$127,'Itens (Locus)'!$A$3:$A$127,$A6,'Itens (Locus)'!$C$3:$C$127,H$4)=0,"",1-SUMIFS('Itens (Locus)'!$D$3:$D$127,'Itens (Locus)'!$A$3:$A$127,$A6,'Itens (Locus)'!$C$3:$C$127,H$4)/SUMIFS('Itens (Locus)'!$E$3:$E$127,'Itens (Locus)'!$A$3:$A$127,$A6,'Itens (Locus)'!$C$3:$C$127,H$4)) -> 0.77777778 | I6: =IF(SUMIFS('Itens (Locus)'!$E$3:$E$127,'Itens (Locus)'!$A$3:$A$127,$A6,'Itens (Locus)'!$C$3:$C$127,I$4)=0,"",1-SUMIFS('Itens (Locus)'!$D$3:$D$127,'Itens (Locus)'!$A$3:$A$127,$A6,'Itens (Locus)'!$C$3:$C$127,I$4)/SUMIFS('Itens (Locus)'!$E$3:$E$127,'Itens (Locus)'!$A$3:$A$127,$A6,'Itens (Locus)'!$C$3:$C$127,I$4)) -> 0.55555556 | J6: =IF(SUMIFS('Itens (Locus)'!$E$3:$E$127,'Itens (Locus)'!$A$3:$A$127,$A6,'Itens (Locus)'!$C$3:$C$127,J$4)=0,"",1-SUMIFS('Itens (Locus)'!$D$3:$D$127,'Itens (Locus)'!$A$3:$A$127,$A6,'Itens (Locus)'!$C$3:$C$127,J$4)/SUMIFS('Itens (Locus)'!$E$3:$E$127,'Itens (Locus)'!$A$3:$A$127,$A6,'Itens (Locus)'!$C$3:$C$127,J$4)) -> 0.625 | K6: =IF(SUMIFS('Itens (Locus)'!$E$3:$E$127,'Itens (Locus)'!$A$3:$A$127,$A6,'Itens (Locus)'!$C$3:$C$127,K$4)=0,"",1-SUMIFS('Itens (Locus)'!$D$3:$D$127,'Itens (Locus)'!$A$3:$A$127,$A6,'Itens (Locus)'!$C$3:$C$127,K$4)/SUMIFS('Itens (Locus)'!$E$3:$E$127,'Itens (Locus)'!$A$3:$A$127,$A6,'Itens (Locus)'!$C$3:$C$127,K$4)) | ... Y6: =IF(SUMIFS('Itens (Locus)'!$E$3:$E$127,'Itens (Locus)'!$A$3:$A$127,$A6,'Itens (Locus)'!$C$3:$C$127,Y$4)=0,"",1-SUMIFS('Itens (Locus)'!$D$3:$D$127,'Itens (Locus)'!$A$3:$A$127,$A6,'Itens (Locus)'!$C$3:$C$127,Y$4)/SUMIFS('Itens (Locus)'!$E$3:$E$127,'Itens (Locus)'!$A$3:$A$127,$A6,'Itens (Locus)'!$C$3:$C$127,Y$4))
A7: Otavio Augusto Soares Greghi | B7: =COUNTIFS(Base!$B$2:$B$1000,$A7) -> 6 | C7: =AVERAGEIFS(Base!$E$2:$E$1000,Base!$B$2:$B$1000,$A7) -> 0.6 | D7: =IF(SUMIFS('Itens (Locus)'!$E$3:$E$127,'Itens (Locus)'!$A$3:$A$127,$A7,'Itens (Locus)'!$C$3:$C$127,D$4)=0,"",1-SUMIFS('Itens (Locus)'!$D$3:$D$127,'Itens (Locus)'!$A$3:$A$127,$A7,'Itens (Locus)'!$C$3:$C$127,D$4)/SUMIFS('Itens (Locus)'!$E$3:$E$127,'Itens (Locus)'!$A$3:$A$127,$A7,'Itens (Locus)'!$C$3:$C$127,D$4)) | E7: =IF(SUMIFS('Itens (Locus)'!$E$3:$E$127,'Itens (Locus)'!$A$3:$A$127,$A7,'Itens (Locus)'!$C$3:$C$127,E$4)=0,"",1-SUMIFS('Itens (Locus)'!$D$3:$D$127,'Itens (Locus)'!$A$3:$A$127,$A7,'Itens (Locus)'!$C$3:$C$127,E$4)/SUMIFS('Itens (Locus)'!$E$3:$E$127,'Itens (Locus)'!$A$3:$A$127,$A7,'Itens (Locus)'!$C$3:$C$127,E$4)) | F7: =IF(SUMIFS('Itens (Locus)'!$E$3:$E$127,'Itens (Locus)'!$A$3:$A$127,$A7,'Itens (Locus)'!$C$3:$C$127,F$4)=0,"",1-SUMIFS('Itens (Locus)'!$D$3:$D$127,'Itens (Locus)'!$A$3:$A$127,$A7,'Itens (Locus)'!$C$3:$C$127,F$4)/SUMIFS('Itens (Locus)'!$E$3:$E$127,'Itens (Locus)'!$A$3:$A$127,$A7,'Itens (Locus)'!$C$3:$C$127,F$4)) | G7: =IF(SUMIFS('Itens (Locus)'!$E$3:$E$127,'Itens (Locus)'!$A$3:$A$127,$A7,'Itens (Locus)'!$C$3:$C$127,G$4)=0,"",1-SUMIFS('Itens (Locus)'!$D$3:$D$127,'Itens (Locus)'!$A$3:$A$127,$A7,'Itens (Locus)'!$C$3:$C$127,G$4)/SUMIFS('Itens (Locus)'!$E$3:$E$127,'Itens (Locus)'!$A$3:$A$127,$A7,'Itens (Locus)'!$C$3:$C$127,G$4)) | H7: =IF(SUMIFS('Itens (Locus)'!$E$3:$E$127,'Itens (Locus)'!$A$3:$A$127,$A7,'Itens (Locus)'!$C$3:$C$127,H$4)=0,"",1-SUMIFS('Itens (Locus)'!$D$3:$D$127,'Itens (Locus)'!$A$3:$A$127,$A7,'Itens (Locus)'!$C$3:$C$127,H$4)/SUMIFS('Itens (Locus)'!$E$3:$E$127,'Itens (Locus)'!$A$3:$A$127,$A7,'Itens (Locus)'!$C$3:$C$127,H$4)) -> 0.8 | I7: =IF(SUMIFS('Itens (Locus)'!$E$3:$E$127,'Itens (Locus)'!$A$3:$A$127,$A7,'Itens (Locus)'!$C$3:$C$127,I$4)=0,"",1-SUMIFS('Itens (Locus)'!$D$3:$D$127,'Itens (Locus)'!$A$3:$A$127,$A7,'Itens (Locus)'!$C$3:$C$127,I$4)/SUMIFS('Itens (Locus)'!$E$3:$E$127,'Itens (Locus)'!$A$3:$A$127,$A7,'Itens (Locus)'!$C$3:$C$127,I$4)) -> 0.6 | J7: =IF(SUMIFS('Itens (Locus)'!$E$3:$E$127,'Itens (Locus)'!$A$3:$A$127,$A7,'Itens (Locus)'!$C$3:$C$127,J$4)=0,"",1-SUMIFS('Itens (Locus)'!$D$3:$D$127,'Itens (Locus)'!$A$3:$A$127,$A7,'Itens (Locus)'!$C$3:$C$127,J$4)/SUMIFS('Itens (Locus)'!$E$3:$E$127,'Itens (Locus)'!$A$3:$A$127,$A7,'Itens (Locus)'!$C$3:$C$127,J$4)) -> 0.4 | K7: =IF(SUMIFS('Itens (Locus)'!$E$3:$E$127,'Itens (Locus)'!$A$3:$A$127,$A7,'Itens (Locus)'!$C$3:$C$127,K$4)=0,"",1-SUMIFS('Itens (Locus)'!$D$3:$D$127,'Itens (Locus)'!$A$3:$A$127,$A7,'Itens (Locus)'!$C$3:$C$127,K$4)/SUMIFS('Itens (Locus)'!$E$3:$E$127,'Itens (Locus)'!$A$3:$A$127,$A7,'Itens (Locus)'!$C$3:$C$127,K$4)) -> 1 | ... Y7: =IF(SUMIFS('Itens (Locus)'!$E$3:$E$127,'Itens (Locus)'!$A$3:$A$127,$A7,'Itens (Locus)'!$C$3:$C$127,Y$4)=0,"",1-SUMIFS('Itens (Locus)'!$D$3:$D$127,'Itens (Locus)'!$A$3:$A$127,$A7,'Itens (Locus)'!$C$3:$C$127,Y$4)/SUMIFS('Itens (Locus)'!$E$3:$E$127,'Itens (Locus)'!$A$3:$A$127,$A7,'Itens (Locus)'!$C$3:$C$127,Y$4))
A8: Gabriel Carneiro de Souza Tritto | B8: =COUNTIFS(Base!$B$2:$B$1000,$A8) -> 16 | C8: =AVERAGEIFS(Base!$E$2:$E$1000,Base!$B$2:$B$1000,$A8) -> 0.728125 | D8: =IF(SUMIFS('Itens (Locus)'!$E$3:$E$127,'Itens (Locus)'!$A$3:$A$127,$A8,'Itens (Locus)'!$C$3:$C$127,D$4)=0,"",1-SUMIFS('Itens (Locus)'!$D$3:$D$127,'Itens (Locus)'!$A$3:$A$127,$A8,'Itens (Locus)'!$C$3:$C$127,D$4)/SUMIFS('Itens (Locus)'!$E$3:$E$127,'Itens (Locus)'!$A$3:$A$127,$A8,'Itens (Locus)'!$C$3:$C$127,D$4)) -> 0.66666667 | E8: =IF(SUMIFS('Itens (Locus)'!$E$3:$E$127,'Itens (Locus)'!$A$3:$A$127,$A8,'Itens (Locus)'!$C$3:$C$127,E$4)=0,"",1-SUMIFS('Itens (Locus)'!$D$3:$D$127,'Itens (Locus)'!$A$3:$A$127,$A8,'Itens (Locus)'!$C$3:$C$127,E$4)/SUMIFS('Itens (Locus)'!$E$3:$E$127,'Itens (Locus)'!$A$3:$A$127,$A8,'Itens (Locus)'!$C$3:$C$127,E$4)) -> 0.66666667 | F8: =IF(SUMIFS('Itens (Locus)'!$E$3:$E$127,'Itens (Locus)'!$A$3:$A$127,$A8,'Itens (Locus)'!$C$3:$C$127,F$4)=0,"",1-SUMIFS('Itens (Locus)'!$D$3:$D$127,'Itens (Locus)'!$A$3:$A$127,$A8,'Itens (Locus)'!$C$3:$C$127,F$4)/SUMIFS('Itens (Locus)'!$E$3:$E$127,'Itens (Locus)'!$A$3:$A$127,$A8,'Itens (Locus)'!$C$3:$C$127,F$4)) -> 0.66666667 | G8: =IF(SUMIFS('Itens (Locus)'!$E$3:$E$127,'Itens (Locus)'!$A$3:$A$127,$A8,'Itens (Locus)'!$C$3:$C$127,G$4)=0,"",1-SUMIFS('Itens (Locus)'!$D$3:$D$127,'Itens (Locus)'!$A$3:$A$127,$A8,'Itens (Locus)'!$C$3:$C$127,G$4)/SUMIFS('Itens (Locus)'!$E$3:$E$127,'Itens (Locus)'!$A$3:$A$127,$A8,'Itens (Locus)'!$C$3:$C$127,G$4)) -> 1 | H8: =IF(SUMIFS('Itens (Locus)'!$E$3:$E$127,'Itens (Locus)'!$A$3:$A$127,$A8,'Itens (Locus)'!$C$3:$C$127,H$4)=0,"",1-SUMIFS('Itens (Locus)'!$D$3:$D$127,'Itens (Locus)'!$A$3:$A$127,$A8,'Itens (Locus)'!$C$3:$C$127,H$4)/SUMIFS('Itens (Locus)'!$E$3:$E$127,'Itens (Locus)'!$A$3:$A$127,$A8,'Itens (Locus)'!$C$3:$C$127,H$4)) -> 0.72727273 | I8: =IF(SUMIFS('Itens (Locus)'!$E$3:$E$127,'Itens (Locus)'!$A$3:$A$127,$A8,'Itens (Locus)'!$C$3:$C$127,I$4)=0,"",1-SUMIFS('Itens (Locus)'!$D$3:$D$127,'Itens (Locus)'!$A$3:$A$127,$A8,'Itens (Locus)'!$C$3:$C$127,I$4)/SUMIFS('Itens (Locus)'!$E$3:$E$127,'Itens (Locus)'!$A$3:$A$127,$A8,'Itens (Locus)'!$C$3:$C$127,I$4)) -> 0.27272727 | J8: =IF(SUMIFS('Itens (Locus)'!$E$3:$E$127,'Itens (Locus)'!$A$3:$A$127,$A8,'Itens (Locus)'!$C$3:$C$127,J$4)=0,"",1-SUMIFS('Itens (Locus)'!$D$3:$D$127,'Itens (Locus)'!$A$3:$A$127,$A8,'Itens (Locus)'!$C$3:$C$127,J$4)/SUMIFS('Itens (Locus)'!$E$3:$E$127,'Itens (Locus)'!$A$3:$A$127,$A8,'Itens (Locus)'!$C$3:$C$127,J$4)) -> 0.78787879 | K8: =IF(SUMIFS('Itens (Locus)'!$E$3:$E$127,'Itens (Locus)'!$A$3:$A$127,$A8,'Itens (Locus)'!$C$3:$C$127,K$4)=0,"",1-SUMIFS('Itens (Locus)'!$D$3:$D$127,'Itens (Locus)'!$A$3:$A$127,$A8,'Itens (Locus)'!$C$3:$C$127,K$4)/SUMIFS('Itens (Locus)'!$E$3:$E$127,'Itens (Locus)'!$A$3:$A$127,$A8,'Itens (Locus)'!$C$3:$C$127,K$4)) -> 1 | ... Y8: =IF(SUMIFS('Itens (Locus)'!$E$3:$E$127,'Itens (Locus)'!$A$3:$A$127,$A8,'Itens (Locus)'!$C$3:$C$127,Y$4)=0,"",1-SUMIFS('Itens (Locus)'!$D$3:$D$127,'Itens (Locus)'!$A$3:$A$127,$A8,'Itens (Locus)'!$C$3:$C$127,Y$4)/SUMIFS('Itens (Locus)'!$E$3:$E$127,'Itens (Locus)'!$A$3:$A$127,$A8,'Itens (Locus)'!$C$3:$C$127,Y$4))
A9: Alex Sandro Pacheoni | B9: =COUNTIFS(Base!$B$2:$B$1000,$A9) -> 5 | C9: =AVERAGEIFS(Base!$E$2:$E$1000,Base!$B$2:$B$1000,$A9) -> 0.76 | D9: =IF(SUMIFS('Itens (Locus)'!$E$3:$E$127,'Itens (Locus)'!$A$3:$A$127,$A9,'Itens (Locus)'!$C$3:$C$127,D$4)=0,"",1-SUMIFS('Itens (Locus)'!$D$3:$D$127,'Itens (Locus)'!$A$3:$A$127,$A9,'Itens (Locus)'!$C$3:$C$127,D$4)/SUMIFS('Itens (Locus)'!$E$3:$E$127,'Itens (Locus)'!$A$3:$A$127,$A9,'Itens (Locus)'!$C$3:$C$127,D$4)) | E9: =IF(SUMIFS('Itens (Locus)'!$E$3:$E$127,'Itens (Locus)'!$A$3:$A$127,$A9,'Itens (Locus)'!$C$3:$C$127,E$4)=0,"",1-SUMIFS('Itens (Locus)'!$D$3:$D$127,'Itens (Locus)'!$A$3:$A$127,$A9,'Itens (Locus)'!$C$3:$C$127,E$4)/SUMIFS('Itens (Locus)'!$E$3:$E$127,'Itens (Locus)'!$A$3:$A$127,$A9,'Itens (Locus)'!$C$3:$C$127,E$4)) | F9: =IF(SUMIFS('Itens (Locus)'!$E$3:$E$127,'Itens (Locus)'!$A$3:$A$127,$A9,'Itens (Locus)'!$C$3:$C$127,F$4)=0,"",1-SUMIFS('Itens (Locus)'!$D$3:$D$127,'Itens (Locus)'!$A$3:$A$127,$A9,'Itens (Locus)'!$C$3:$C$127,F$4)/SUMIFS('Itens (Locus)'!$E$3:$E$127,'Itens (Locus)'!$A$3:$A$127,$A9,'Itens (Locus)'!$C$3:$C$127,F$4)) | G9: =IF(SUMIFS('Itens (Locus)'!$E$3:$E$127,'Itens (Locus)'!$A$3:$A$127,$A9,'Itens (Locus)'!$C$3:$C$127,G$4)=0,"",1-SUMIFS('Itens (Locus)'!$D$3:$D$127,'Itens (Locus)'!$A$3:$A$127,$A9,'Itens (Locus)'!$C$3:$C$127,G$4)/SUMIFS('Itens (Locus)'!$E$3:$E$127,'Itens (Locus)'!$A$3:$A$127,$A9,'Itens (Locus)'!$C$3:$C$127,G$4)) | H9: =IF(SUMIFS('Itens (Locus)'!$E$3:$E$127,'Itens (Locus)'!$A$3:$A$127,$A9,'Itens (Locus)'!$C$3:$C$127,H$4)=0,"",1-SUMIFS('Itens (Locus)'!$D$3:$D$127,'Itens (Locus)'!$A$3:$A$127,$A9,'Itens (Locus)'!$C$3:$C$127,H$4)/SUMIFS('Itens (Locus)'!$E$3:$E$127,'Itens (Locus)'!$A$3:$A$127,$A9,'Itens (Locus)'!$C$3:$C$127,H$4)) -> 1 | I9: =IF(SUMIFS('Itens (Locus)'!$E$3:$E$127,'Itens (Locus)'!$A$3:$A$127,$A9,'Itens (Locus)'!$C$3:$C$127,I$4)=0,"",1-SUMIFS('Itens (Locus)'!$D$3:$D$127,'Itens (Locus)'!$A$3:$A$127,$A9,'Itens (Locus)'!$C$3:$C$127,I$4)/SUMIFS('Itens (Locus)'!$E$3:$E$127,'Itens (Locus)'!$A$3:$A$127,$A9,'Itens (Locus)'!$C$3:$C$127,I$4)) -> 0.6 | J9: =IF(SUMIFS('Itens (Locus)'!$E$3:$E$127,'Itens (Locus)'!$A$3:$A$127,$A9,'Itens (Locus)'!$C$3:$C$127,J$4)=0,"",1-SUMIFS('Itens (Locus)'!$D$3:$D$127,'Itens (Locus)'!$A$3:$A$127,$A9,'Itens (Locus)'!$C$3:$C$127,J$4)/SUMIFS('Itens (Locus)'!$E$3:$E$127,'Itens (Locus)'!$A$3:$A$127,$A9,'Itens (Locus)'!$C$3:$C$127,J$4)) -> 0.73333333 | K9: =IF(SUMIFS('Itens (Locus)'!$E$3:$E$127,'Itens (Locus)'!$A$3:$A$127,$A9,'Itens (Locus)'!$C$3:$C$127,K$4)=0,"",1-SUMIFS('Itens (Locus)'!$D$3:$D$127,'Itens (Locus)'!$A$3:$A$127,$A9,'Itens (Locus)'!$C$3:$C$127,K$4)/SUMIFS('Itens (Locus)'!$E$3:$E$127,'Itens (Locus)'!$A$3:$A$127,$A9,'Itens (Locus)'!$C$3:$C$127,K$4)) | ... Y9: =IF(SUMIFS('Itens (Locus)'!$E$3:$E$127,'Itens (Locus)'!$A$3:$A$127,$A9,'Itens (Locus)'!$C$3:$C$127,Y$4)=0,"",1-SUMIFS('Itens (Locus)'!$D$3:$D$127,'Itens (Locus)'!$A$3:$A$127,$A9,'Itens (Locus)'!$C$3:$C$127,Y$4)/SUMIFS('Itens (Locus)'!$E$3:$E$127,'Itens (Locus)'!$A$3:$A$127,$A9,'Itens (Locus)'!$C$3:$C$127,Y$4))
