Workbook

Sheet Resumo
A1: Análise Natasha WhatsApp — consolidado dos 116 telefones únicos
A2: Fontes: telefones_unicos_consolidado.xlsx (116 números) + exportação do painel (natasha_whatsapp_2026-10-13_1227.xlsx, análises de 13/10/2026). Todos os números são fórmulas sobre a aba Consolidado.
A4: Cobertura
A5: Telefones únicos na planilha | B5: =COUNTA(Consolidado!$B$2:$B$117) -> 116
A6: Sem nome | B6: =COUNTIF(Consolidado!$D$2:$D$117,"Sem nome") -> 41 | C6: =IFERROR(B6/$B$5,"") -> 0.35344828
A7: Cliente | B7: =COUNTIF(Consolidado!$D$2:$D$117,"Cliente") -> 58 | C7: =IFERROR(B7/$B$5,"") -> 0.5
A8: Com nome | B8: =COUNTIF(Consolidado!$D$2:$D$117,"Com nome") -> 17 | C8: =IFERROR(B8/$B$5,"") -> 0.14655172
A9: Analisados | B9: =COUNTA(Consolidado!$I$2:$I$117) -> 116 | C9: =IFERROR(B9/$B$5,"") -> 1
A10: Planilha de origem: só no funil | B10: =COUNTIF(Consolidado!$H$2:$H$117,"Só no funil") -> 66 | C10: =IFERROR(B10/$B$5,"") -> 0.56896552
A11: Planilha de origem: só nos disparos | B11: =COUNTIF(Consolidado!$H$2:$H$117,"Só nos disparos") -> 41 | C11: =IFERROR(B11/$B$5,"") -> 0.35344828
A12: Planilha de origem: nas duas | B12: =COUNTIF(Consolidado!$H$2:$H$117,"Nas duas planilhas") -> 9 | C12: =IFERROR(B12/$B$5,"") -> 0.077586207
A14: Status no Dryve Pro
A15: Perdido | B15: =COUNTIF(Consolidado!$N$2:$N$117,"Perdido") -> 101 | C15: =IFERROR(B15/$B$5,"") -> 0.87068966
A16: Outro (com etapa) | B16: =COUNTIF(Consolidado!$N$2:$N$117,"Outro") -> 15 | C16: =IFERROR(B16/$B$5,"") -> 0.12931034
A17: Etapa: Aprovado | B17: =COUNTIF(Consolidado!$O$2:$O$117,"Aprovado") -> 6
A18: Etapa: Reprovado | B18: =COUNTIF(Consolidado!$O$2:$O$117,"Reprovado") -> 6
A19: Etapa: Enviado para locadora | B19: =COUNTIF(Consolidado!$O$2:$O$117,"Enviado para locadora") -> 2
A20: Etapa: Contato efetivo | B20: =COUNTIF(Consolidado!$O$2:$O$117,"Contato efetivo") -> 1
A21: Status correto (Perdido) | B21: =COUNTIFS(Consolidado!$N$2:$N$117,"Perdido",Consolidado!$Q$2:$Q$117,"Sim") -> 7 | C21: =IFERROR(B21/$B$15,"") -> 0.069306931
A23: Atendimento
A24: Sem atendimento | B24: =COUNTIF(Consolidado!$K$2:$K$117,"Não houve atendimento") -> 93 | C24: =IFERROR(B24/$B$5,"") -> 0.80172414
A25: A IA atendeu | B25: =COUNTIF(Consolidado!$K$2:$K$117,"Sim, a IA atendeu") -> 23 | C25: =IFERROR(B25/$B$5,"") -> 0.19827586
A26: Cliente encerrou o canal sem continuar | B26: =COUNTIF(Consolidado!$L$2:$L$117,"Cliente encerrou o canal sem continuar") -> 47 | C26: =IFERROR(B26/$B$24,"") -> 0.50537634
A27: Cliente não interagiu | B27: =COUNTIF(Consolidado!$L$2:$L$117,"Cliente não interagiu") -> 27 | C27: =IFERROR(B27/$B$24,"") -> 0.29032258
A28: Sem interação / sem resposta (Xsales) | B28: =COUNTIF(Consolidado!$L$2:$L$117,"Sem interação / sem resposta (Xsales)") -> 19 | C28: =IFERROR(B28/$B$24,"") -> 0.20430108
A30: Motivo do perdido (101 perdidos)
A31: Registrado como Motorista de App | B31: =COUNTIFS(Consolidado!$N$2:$N$117,"Perdido",Consolidado!$R$2:$R$117,"Motorista de App") -> 95 | C31: =IFERROR(B31/$B$15,"") -> 0.94059406
A32: Realmente motorista de app (confirmado) | B32: =COUNTIFS(Consolidado!$N$2:$N$117,"Perdido",Consolidado!$R$2:$R$117,"Motorista de App",Consolidado!$T$2:$T$117,"Sim") -> 6 | C32: =IFERROR(B32/$B$15,"") -> 0.059405941
A33: Não era motorista de app | B33: =B15-B32 -> 95 | C33: =IFERROR(B33/$B$15,"") -> 0.94059406
A35: Motivo real informado (quando o motivo registrado estava incorreto)
A36: Limpeza de board | B36: =COUNTIF(Consolidado!$U$2:$U$117,"Limpeza de board") -> 11
A37: Cotando / Pesquisando | B37: =COUNTIF(Consolidado!$U$2:$U$117,"Cotando / Pesquisando") -> 2
A38: Preferiu comprar o carro | B38: =COUNTIF(Consolidado!$U$2:$U$117,"Preferiu comprar o carro") -> 1
A39: Preço não agradou | B39: =COUNTIF(Consolidado!$U$2:$U$117,"Preço não agradou") -> 1
A40: Sem motivo real informado | B40: =COUNTIFS(Consolidado!$N$2:$N$117,"Perdido",Consolidado!$T$2:$T$117,"Não",Consolidado!$U$2:$U$117,"") -> 79

Sheet Consolidado
A1: # | B1: Telefone | C1: Nome(s) | D1: Grupo | E1: Esteira(s) | F1: Origem | G1: Data(s) do pedido | H1: Planilha de origem | I1: Data da análise | J1: Hora | K1: Atendimento | L1: Motivo sem atendimento | M1: Motivo sem atendimento (como digitado) | N1: Status no Dryve Pro | O1: Etapa (se Outro) | P1: Por quê da etapa | Q1: Status correto | R1: Motivo registrado | S1: Por quê do motivo | T1: Motivo correto? | U1: Motivo real (se incorreto) | V1: Observação | W1: Validar depois (tem nome)
A2: 1 | B2: +55 12 99225-4422 | C2: (sem nome) | D2: Sem nome | H2: Só nos disparos | I2: 13/10/2026 | J2: 11:25:03 | K2: Não houve atendimento | L2: Cliente encerrou o canal sem continuar | M2: Cliente encerrou o canal sem continuar | N2: Perdido | Q2: Não | R2: Motorista de App | T2: Não
A3: 2 | B3: +55 12 99720-0045 | C3: (sem nome) | D3: Sem nome | H3: Só nos disparos | I3: 13/10/2026 | J3: 11:42:44 | K3: Não houve atendimento | L3: Cliente encerrou o canal sem continuar | M3: Cliente encerrou o canal sem continuar | N3: Perdido | Q3: Não | R3: Motorista de App | T3: Não
A4: 3 | B4: +55 13 97409-5767 | C4: (sem nome) | D4: Sem nome | H4: Só nos disparos | I4: 13/10/2026 | J4: 11:26:36 | K4: Não houve atendimento | L4: Cliente encerrou o canal sem continuar | M4: Cliente encerrou o canal sem continuar | N4: Perdido | Q4: Não | R4: Motorista de App | T4: Não
A5: 4 | B5: +55 13 98881-0408 | C5: (sem nome) | D5: Sem nome | H5: Só nos disparos | I5: 13/10/2026 | J5: 11:28:30 | K5: Não houve atendimento | L5: Cliente encerrou o canal sem continuar | M5: Cliente encerrou o canal sem continuar | N5: Perdido | Q5: Não | R5: Motorista de App | T5: Não
A6: 5 | B6: +55 13 99777-0394 | C6: (sem nome) | D6: Sem nome | H6: Só nos disparos | I6: 13/10/2026 | J6: 11:57:13 | K6: Sim, a IA atendeu | N6: Perdido | Q6: Não | R6: Motorista de App | T6: Não | U6: Preço não agradou
A7: 6 | B7: +55 13 99789-7524 | C7: (sem nome) | D7: Sem nome | H7: Só nos disparos | I7: 13/10/2026 | J7: 11:59:56 | K7: Sim, a IA atendeu | N7: Outro | O7: Reprovado | Q7: Sim
A8: 7 | B8: +55 15 99769-5422 | C8: (sem nome) | D8: Sem nome | H8: Só nos disparos | I8: 13/10/2026 | J8: 11:33:42 | K8: Não houve atendimento | L8: Cliente encerrou o canal sem continuar | M8: Cliente encerrou o canal sem continuar | N8: Perdido | Q8: Não | R8: Motorista de App | T8: Não
A9: 8 | B9: +55 17 98194-0191 | C9: (sem nome) | D9: Sem nome | H9: Só nos disparos | I9: 13/10/2026 | J9: 11:46:14 | K9: Não houve atendimento | L9: Cliente encerrou o canal sem continuar | M9: Cliente encerrou o canal sem continuar | N9: Perdido | Q9: Não | R9: Motorista de App | T9: Não
A10: 9 | B10: +55 32 98713-5306 | C10: (sem nome) | D10: Sem nome | H10: Só nos disparos | I10: 13/10/2026 | J10: 11:55:51 | K10: Não houve atendimento | L10: Cliente encerrou o canal sem continuar | M10: Cliente encerrou o canal sem continuar | N10: Perdido | Q10: Não | R10: Motorista de App | T10: Não
A11: 10 | B11: +55 34 99777-7624 | C11: (sem nome) | D11: Sem nome | H11: Só nos disparos | I11: 13/10/2026 | J11: 11:53:10 | K11: Não houve atendimento | L11: Cliente encerrou o canal sem continuar | M11: Cliente encerrou o canal sem continuar | N11: Perdido | Q11: Não | R11: Motorista de App | T11: Não
A12: 11 | B12: +55 35 91014-8874 | C12: (sem nome) | D12: Sem nome | H12: Só nos disparos | I12: 13/10/2026 | J12: 11:32:03 | K12: Não houve atendimento | L12: Cliente não interagiu | M12: Cliente não interagiu | N12: Perdido | Q12: Não | R12: Motorista de App | T12: Não
A13: 12 | B13: +55 35 98411-9515 | C13: (sem nome) | D13: Sem nome | H13: Só nos disparos | I13: 13/10/2026 | J13: 11:43:56 | K13: Não houve atendimento | L13: Cliente encerrou o canal sem continuar | M13: Cliente encerrou o canal sem continuar | N13: Perdido | Q13: Não | R13: Motorista de App | T13: Não
A14: 13 | B14: +55 35 99221-6024 | C14: (sem nome) | D14: Sem nome | H14: Só nos disparos | I14: 13/10/2026 | J14: 11:49:47 | K14: Não houve atendimento | L14: Cliente encerrou o canal sem continuar | M14: Cliente encerrou o canal sem continuar | N14: Perdido | Q14: Não | R14: Motorista de App | T14: Não
A15: 14 | B15: +55 38 99168-8186 | C15: (sem nome) | D15: Sem nome | H15: Só nos disparos | I15: 13/10/2026 | J15: 11:51:33 | K15: Sim, a IA atendeu | N15: Perdido | Q15: Sim | R15: Motorista de App | T15: Sim
A16: 15 | B16: +55 38 99182-7162 | C16: (sem nome) | D16: Sem nome | H16: Só nos disparos | I16: 13/10/2026 | J16: 11:58:35 | K16: Sim, a IA atendeu | N16: Perdido | Q16: Sim | R16: Motorista de App | T16: Sim
A17: 16 | B17: +55 38 99854-9962 | C17: (sem nome) | D17: Sem nome | H17: Só nos disparos | I17: 13/10/2026 | J17: 11:40:17 | K17: Não houve atendimento | L17: Cliente encerrou o canal sem continuar | M17: Cliente encerrou o canal sem continuar | N17: Perdido | Q17: Não | R17: Motorista de App | T17: Não
A18: 17 | B18: +55 44 99991-2973 | C18: (sem nome) | D18: Sem nome | H18: Só nos disparos | I18: 13/10/2026 | J18: 11:27:37 | K18: Não houve atendimento | L18: Cliente encerrou o canal sem continuar | M18: Cliente encerrou o canal sem continuar | N18: Perdido | Q18: Não | R18: Motorista de App | T18: Não
A19: 18 | B19: +55 45 99820-8401 | C19: (sem nome) | D19: Sem nome | H19: Só nos disparos | I19: 13/10/2026 | J19: 11:29:03 | K19: Não houve atendimento | L19: Cliente encerrou o canal sem continuar | M19: Cliente encerrou o canal sem continuar | N19: Perdido | Q19: Não | R19: Motorista de App | T19: Não
A20: 19 | B20: +55 61 98199-0868 | C20: (sem nome) | D20: Sem nome | H20: Só nos disparos | I20: 13/10/2026 | J20: 11:58:17 | K20: Não houve atendimento | L20: Cliente encerrou o canal sem continuar | M20: Cliente encerrou o canal sem continuar | N20: Perdido | Q20: Não | R20: Motorista de App | T20: Não
A21: 20 | B21: +55 61 98452-2540 | C21: (sem nome) | D21: Sem nome | H21: Só nos disparos | I21: 13/10/2026 | J21: 11:39:02 | K21: Sim, a IA atendeu | N21: Perdido | Q21: Sim | R21: Motorista de App | T21: Sim
A22: 21 | B22: +55 61 98597-7180 | C22: (sem nome) | D22: Sem nome | H22: Só nos disparos | I22: 13/10/2026 | J22: 12:01:36 | K22: Não houve atendimento | L22: Cliente encerrou o canal sem continuar | M22: Cliente encerrou o canal sem continuar | N22: Perdido | Q22: Não | R22: Motorista de App | T22: Não
A23: 22 | B23: +55 61 99554-4068 | C23: (sem nome) | D23: Sem nome | H23: Só nos disparos | I23: 13/10/2026 | J23: 11:43:25 | K23: Não houve atendimento | L23: Cliente encerrou o canal sem continuar | M23: Cliente encerrou o canal sem continuar | N23: Perdido | Q23: Não | R23: Motorista de App | T23: Não
A24: 23 | B24: +55 61 99991-8123 | C24: (sem nome) | D24: Sem nome | H24: Só nos disparos | I24: 13/10/2026 | J24: 11:47:29 | K24: Sim, a IA atendeu | N24: Perdido | Q24: Não | R24: Motorista de App | T24: Não | U24: Limpeza de board
A25: 24 | B25: +55 67 93300-2295 | C25: (sem nome) | D25: Sem nome | H25: Só nos disparos | I25: 13/10/2026 | J25: 12:03:23 | K25: Não houve atendimento | L25: Cliente encerrou o canal sem continuar | M25: Cliente encerrou o canal sem continuar | N25: Perdido | Q25: Não | R25: Motorista de App | T25: Não
A26: 25 | B26: +55 81 98169-7019 | C26: (sem nome) | D26: Sem nome | H26: Só nos disparos | I26: 13/10/2026 | J26: 11:31:09 | K26: Sim, a IA atendeu | N26: Perdido | Q26: Não | R26: Motorista de App | T26: Não | U26: Cotando / Pesquisando
A27: 26 | B27: +55 81 98438-0034 | C27: (sem nome) | D27: Sem nome | H27: Só nos disparos | I27: 13/10/2026 | J27: 11:41:00 | K27: Não houve atendimento | L27: Cliente encerrou o canal sem continuar | M27: Cliente encerrou o canal sem continuar | N27: Perdido | Q27: Não | R27: Motorista de App | T27: Não
A28: 27 | B28: +55 81 98585-1643 | C28: (sem nome) | D28: Sem nome | H28: Só nos disparos | I28: 13/10/2026 | J28: 11:54:37 | K28: Sim, a IA atendeu | N28: Perdido | Q28: Não | R28: Motorista de App | T28: Não | U28: Preferiu comprar o carro
A29: 28 | B29: +55 81 98717-4093 | C29: (sem nome) | D29: Sem nome | H29: Só nos disparos | I29: 13/10/2026 | J29: 11:34:09 | K29: Não houve atendimento | L29: Cliente encerrou o canal sem continuar | M29: Cliente encerrou o canal sem continuar | N29: Perdido | Q29: Não | R29: Motorista de App | T29: Não
A30: 29 | B30: +55 81 98749-7973 | C30: (sem nome) | D30: Sem nome | H30: Só nos disparos | I30: 13/10/2026 | J30: 11:50:25 | K30: Não houve atendimento | L30: Cliente encerrou o canal sem continuar | M30: Cliente encerrou o canal sem continuar | N30: Perdido | Q30: Não | R30: Motorista de App | T30: Não
A31: 30 | B31: +55 81 99338-9308 | C31: (sem nome) | D31: Sem nome | H31: Só nos disparos | I31: 13/10/2026 | J31: 11:24:18 | K31: Não houve atendimento | L31: Cliente encerrou o canal sem continuar | M31: Cliente encerrou o canal sem continuar | N31: Perdido | Q31: Não | R31: Motorista de App | T31: Não
A32: 31 | B32: +55 81 99371-2563 | C32: (sem nome) | D32: Sem nome | H32: Só nos disparos | I32: 13/10/2026 | J32: 11:29:43 | K32: Não houve atendimento | L32: Cliente encerrou o canal sem continuar | M32: Cliente encerrou o canal sem continuar | N32: Perdido | Q32: Não | R32: Motorista de App | T32: Não
A33: 32 | B33: +55 81 99746-8542 | C33: (sem nome) | D33: Sem nome | H33: Só nos disparos | I33: 13/10/2026 | J33: 11:41:55 | K33: Não houve atendimento | L33: Cliente encerrou o canal sem continuar | M33: Cliente encerrou o canal sem continuar | N33: Perdido | Q33: Não | R33: Motorista de App | T33: Não
A34: 33 | B34: +55 81 99794-2226 | C34: (sem nome) | D34: Sem nome | H34: Só nos disparos | I34: 13/10/2026 | J34: 12:02:23 | K34: Não houve atendimento | L34: Cliente encerrou o canal sem continuar | M34: Cliente encerrou o canal sem continuar | N34: Perdido | Q34: Não | R34: Motorista de App | T34: Não
A35: 34 | B35: +55 81 99963-7030 | C35: (sem nome) | D35: Sem nome | H35: Só nos disparos | I35: 13/10/2026 | J35: 11:45:31 | K35: Não houve atendimento | L35: Cliente encerrou o canal sem continuar | M35: Cliente encerrou o canal sem continuar | N35: Perdido | Q35: Não | R35: Motorista de App | T35: Não
A36: 35 | B36: +55 87 99900-1192 | C36: (sem nome) | D36: Sem nome | H36: Só nos disparos | I36: 13/10/2026 | J36: 11:51:09 | K36: Não houve atendimento | L36: Cliente encerrou o canal sem continuar | M36: Cliente encerrou o canal sem continuar | N36: Perdido | Q36: Não | R36: Motorista de App | T36: Não
A37: 36 | B37: +55 91 98311-4277 | C37: (sem nome) | D37: Sem nome | H37: Só nos disparos | I37: 13/10/2026 | J37: 11:55:01 | K37: Sim, a IA atendeu | N37: Perdido | Q37: Sim | R37: Motorista de App | T37: Sim
A38: 37 | B38: +55 92 98128-3372 | C38: (sem nome) | D38: Sem nome | H38: Só nos disparos | I38: 13/10/2026 | J38: 11:48:44 | K38: Não houve atendimento | L38: Cliente encerrou o canal sem continuar | M38: Cliente encerrou o canal sem continuar | N38: Perdido | Q38: Não | R38: Motorista de App | T38: Não
A39: 38 | B39: +55 92 99290-9401 | C39: (sem nome) | D39: Sem nome | H39: Só nos disparos | I39: 13/10/2026 | J39: 11:32:28 | K39: Não houve atendimento | L39: Cliente encerrou o canal sem continuar | M39: Cliente encerrou o canal sem continuar | N39: Perdido | Q39: Não | R39: Motorista de App | T39: Não
A40: 39 | B40: +55 92 99429-8958 | C40: (sem nome) | D40: Sem nome | H40: Só nos disparos | I40: 13/10/2026 | J40: 12:04:03 | K40: Sim, a IA atendeu | N40: Perdido | Q40: Sim | R40: Motorista de App | T40: Sim
...

Sheet Validar depois (com nome)
A1: # | B1: Telefone | C1: Nome(s) | D1: Esteira(s) | E1: Planilha de origem | F1: Atendimento | G1: Status no Dryve Pro | H1: Etapa (se Outro) | I1: Status correto | J1: Motivo registrado | K1: Motivo correto? | L1: Motivo real (se incorreto) | M1: Observação
A2: 1 | B2: +55 11 97755-7558 | C2: João Marcos de Oliveira Santana | D2: Localiza | E2: Só no funil | F2: Sim, a IA atendeu | G2: Outro | H2: Reprovado | I2: Sim
A3: 2 | B3: +55 11 99301-7675 | C3: ingrid paula da silva feitosa | D3: Localiza | E3: Nas duas planilhas | F3: Sim, a IA atendeu | G3: Outro | H3: Reprovado | I3: Sim
A4: 3 | B4: +55 16 99620-7955 | C4: José Augusto Bononi | D4: Movida | E4: Só no funil | F4: Sim, a IA atendeu | G4: Outro | H4: Aprovado | I4: Sim
A5: 4 | B5: +55 19 99169-8003 | C5: WELLINGTON DE SOUZA | D5: Condicional | E5: Só no funil | F5: Não houve atendimento | G5: Outro | H5: Aprovado | I5: Sim
A6: 5 | B6: +55 21 99193-1717 | C6: JENYFER LORRANA LOPES DA SILVA MOREIRA | D6: Movida | E6: Nas duas planilhas | F6: Sim, a IA atendeu | G6: Outro | H6: Aprovado | I6: Sim
A7: 6 | B7: +55 37 98833-8689 | C7: Matheus de Oliveira Pena Costa | D7: Condicional | E7: Só no funil | F7: Não houve atendimento | G7: Outro | H7: Aprovado | I7: Sim
A8: 7 | B8: +55 61 99997-4248 | C8: Moises Rodrigues Fernandes | D8: Localiza | E8: Só no funil | F8: Não houve atendimento | G8: Perdido | I8: Não | J8: Limpeza de board | K8: Não | L8: Limpeza de board
A9: 8 | B9: +55 62 98103-6095 | C9: Geison | Cliente | E9: Só no funil | F9: Não houve atendimento | G9: Perdido | I9: Não | J9: Motorista de App | K9: Não | L9: Limpeza de board
A10: 9 | B10: +55 62 99178-6861 | C10: Rhilza Victoria Pereira de Matos | D10: Localiza | E10: Só no funil | F10: Sim, a IA atendeu | G10: Outro | H10: Enviado para locadora | I10: Sim
A11: 10 | B11: +55 75 99966-1525 | C11: Hernandes Santos Muniz | D11: Localiza | E11: Só no funil | F11: Não houve atendimento | G11: Outro | H11: Aprovado | I11: Sim
A12: 11 | B12: +55 79 99658-5424 | C12: André Edson Buche | D12: Localiza | E12: Só no funil | F12: Não houve atendimento | G12: Outro | H12: Contato efetivo | I12: Sim
A13: 12 | B13: +55 81 99633-6445 | C13: Ivanildo Ferreira dos Santos filho | D13: Localiza | E13: Só no funil | F13: Não houve atendimento | G13: Outro | H13: Aprovado | I13: Sim
A14: 13 | B14: +55 83 98634-1651 | C14: Kallinne kellen de Sousa Albuquerque | D14: Localiza | E14: Só no funil | F14: Não houve atendimento | G14: Perdido | I14: Não | J14: Outro | K14: Não
A15: 14 | B15: +55 84 98863-2798 | C15: Alikson thiago Teixeira de lima | D15: Localiza | E15: Nas duas planilhas | F15: Sim, a IA atendeu | G15: Outro | H15: Reprovado | I15: Sim
A16: 15 | B16: +55 93 99257-6374 | C16: Mara junia galucio de sousa | D16: Localiza | E16: Só no funil | F16: Sim, a IA atendeu | G16: Outro | H16: Enviado para locadora | I16: Sim
A17: 16 | B17: +55 93 99902-3782 | C17: Bruno Estevam Mendes | D17: Localiza | E17: Só no funil | F17: Não houve atendimento | G17: Outro | H17: Reprovado | I17: Sim
A18: 17 | B18: +55 94 98410-9400 | C18: Nataniel Moreira de Souza | D18: Condicional | E18: Só no funil | F18: Não houve atendimento | G18: Perdido | I18: Não | J18: Motorista de App | K18: Não
